Workbook
Name Dulieutho: 'Dữ liệu thô'!$1:$1048576

Sheet Dữ liệu thô
A1: 1 | B1: 2 | C1: 3 | D1: 4 | E1: 5 | F1: 6 | G1: 7 | H1: 8 | I1: 9 | J1: 10 | K1: 11 | L1: 12 | M1: 13 | N1: 14 | O1: 15 | P1: 16 | Q1: 17 | R1: 18 | S1: 19 | T1: 20 | U1: 21 | V1: 22 | W1: 23 | X1: 24 | Y1: 25 | Z1: 26 | AA1: 27 | AB1: 28 | AC1: 29 | AD1: 30 | AE1: 31 | AF1: 32 | AG1: 33 | AH1: 34 | AI1: 35 | AJ1: 36 | AK1: 37 | AL1: 38 | AM1: 39 | AN1: 40 | AO1: 41 | AP1: 42 | AQ1: 43 | AR1: 44 | AS1: 45 | AT1: 46 | AU1: 47 | AV1: 48 | AW1: 49 | AX1: 50
A2: Nhãn Hàng | B2: Băng keo (10 cuộn / cây) | C2: Bánh mì hamburger (4 cái / bịch) | D2: Bánh Mì Hotdog ( 4 cái/bịch) | E2: Bánh mì pita (10 cái/bịch) | F2: Bánh mì sandwich (24m/bịch) | G2: Banner 4 Loại Bánh 20.000 ( mau moi 22.000) | H2: Bao tay xốp ( 1kg/ bịch) | I2: Bịt rác đen lớn (25Cai/KG) | J2: Bột chanh 1kg/tui | K2: Bột Kem Sữa Cacao (500g / túi) | L2: Chà bông xốp ( 1kg/bịch) | M2: Dầu ăn ( 2 lit/bình ) | N2: Đường trắng (12kg/bao) | O2: Giấy gói bánh mì ( 500 tờ/xấp) | P2: Hộp Giấy Buger Gà (150 cái/ thùng) | Q2: Hộp Giấy Pita Gà (100 cái/ xấp) | R2: Hộp Giấy Sanwich (100 cái/ xấp) | S2: Jam Bon đặt biệt ( 250g/bịch) | T2: Khăn giấy (100 tờ/ xấp) | U2: Ly giấy in logo 1p30s (1000 cái/thùng) | V2: Màng ép ly 1p30s ( 3600ly/ cuộn) | W2: Miếng thịt bò hỗn hợp (30 miếng/thùng) | X2: Miếng thịt burger gà (60 miếng/thùng) | Y2: Miếng thịt burger Tôm (30 miếng/thùng) | Z2: Miếng thịt hamburger (90 miếng/thùng) | AA2: Nắp ly nhựa phi 90 ( 50 cái/ bao) | AB2: Nước Ngọt pesi 1.5 lit / chai (12 chai/ thùng) | AC2: ống hút Giấy đầu nhọn (250 cây/ bao) | AD2: Pate gan (0.5 kg / bịch) | AE2: Sốt Phô Mai (0.5kg/túi) | AF2: Sữa bột 25kg/bịch) | AG2: Tạp Dề | AH2: Trà Đen (1kg/ bich) | AI2: Túi dựng ly 1p30s (Bột sắn + Phụ Gia) ( 192 cái / kg) | AJ2: Túi Giấy Đựng Pita (100 cái/ xấp) | AK2: Túi Giấy Hotdog (100 cái/ xấp) | AL2: Tương cà lớn (2Lit/Bình) | AM2: Tương Mayonaise ( 1kg/bịch) | AN2: Tương mù tạc (0.5kg/ bịch) | AO2: Tương ớt Cholimex (270gram/chai) | AP2: Xúc Xích ( 10 cây / 0.5kg) | AQ2: (trống) | AR2: Muối Tiêu ( 06 chai / lốc) | AS2: Nón Ăn Sáng | AT2: Dưa chuột muối OTTOGI (250g/túi, 35 túi/thùng) | AU2: Kệ Inox Di Động | AV2: Hộp Sandwich Gà | AW2: Khẩu trang y tế (50 cái / hộp) | AX2: Tờ rơi giá bò 22.000, gà 27.000 (500 tờ / xấp)
A3: F1-021 | C3: 208 | D3: 36 | E3: 70 | F3: 96 | J3: 1 | K3: 2 | O3: 500 | X3: 180 | Y3: 60 | Z3: 180 | AB3: 12 | AE3: 0.5 | AI3: 1 | AL3: 2 | AO3: 2 | AP3: 30
A4: F1-022 | C4: 888 | D4: 268 | E4: 230 | F4: 384 | H4: 1 | J4: 2 | K4: 2.5 | L4: 2 | M4: 24 | O4: 500 | P4: 450 | Q4: 100 | R4: 200 | S4: 3.5 | T4: 3 | U4: 1000 | X4: 60 | AA4: 1500 | AB4: 60 | AC4: 4 | AE4: 1 | AI4: 7 | AJ4: 100 | AK4: 300 | AL4: 14 | AM4: 10 | AO4: 7 | AP4: 220
A5: F1-076 | B5: 20 | C5: 1288 | D5: 244 | E5: 290 | F5: 48 | M5: 36 | O5: 1000 | P5: 450 | R5: 100 | S5: 1.5 | U5: 3000 | V5: 1 | X5: 1020 | Y5: 90 | Z5: 180 | AB5: 48 | AC5: 12 | AD5: 3 | AE5: 1 | AI5: 3 | AJ5: 400 | AK5: 300 | AL5: 14 | AM5: 2 | AN5: 1 | AO5: 11 | AP5: 140
A6: F1-115 | C6: 492 | D6: 92 | E6: 70 | F6: 144 | K6: 4 | L6: 1 | M6: 10 | P6: 300 | R6: 100 | S6: 1 | U6: 1000 | X6: 240 | Y6: 60 | Z6: 270 | AA6: 600 | AB6: 36 | AC6: 4 | AE6: 2 | AH6: 1 | AI6: 2 | AL6: 2 | AM6: 2 | AO6: 6 | AP6: 70
A7: F1-176 | C7: 460 | D7: 48 | E7: 60 | F7: 24 | K7: 9 | M7: 6 | P7: 450 | V7: 1 | X7: 660 | Y7: 30 | Z7: 90 | AB7: 36 | AD7: 1 | AH7: 2 | AI7: 6 | AJ7: 100 | AK7: 200 | AL7: 12 | AM7: 4 | AP7: 120
A8: F1-184 | B8: 10 | C8: 3480 | D8: 656 | E8: 500 | F8: 816 | H8: 1 | J8: 10 | K8: 32 | L8: 1 | M8: 12 | N8: 12 | O8: 1500 | P8: 2100 | Q8: 300 | R8: 300 | S8: 4 | U8: 5000 | V8: 1 | X8: 2520 | Y8: 390 | Z8: 1440 | AB8: 156 | AC8: 20 | AD8: 1 | AE8: 1.5 | AF8: 25 | AH8: 3 | AI8: 23 | AJ8: 300 | AK8: 700 | AL8: 18 | AM8: 18 | AN8: 1.5 | AO8: 2 | AP8: 400
A9: F1-191 | B9: 10 | C9: 1152 | D9: 148 | E9: 350 | F9: 360 | G9: 2 | H9: 2 | J9: 5 | K9: 3 | L9: 1 | M9: 48 | N9: 24 | O9: 1000 | R9: 200 | S9: 1.5 | U9: 2000 | V9: 1 | W9: 120 | X9: 900 | Y9: 240 | Z9: 540 | AB9: 48 | AC9: 9 | AD9: 3 | AE9: 3 | AF9: 25 | AH9: 2 | AI9: 9 | AJ9: 400 | AK9: 200 | AL9: 14 | AM9: 12 | AN9: 1.5 | AO9: 21 | AP9: 230
A10: F1-209 | C10: 728 | D10: 100 | E10: 210 | F10: 288 | H10: 1 | J10: 3 | K10: 4 | L10: 1 | M10: 96 | N10: 24 | O10: 1000 | S10: 0.5 | U10: 1000 | V10: 1 | W10: 210 | X10: 1740 | Y10: 360 | Z10: 1440 | AB10: 60 | AC10: 4 | AD10: 1 | AE10: 2 | AF10: 25 | AH10: 1 | AI10: 6 | AJ10: 200 | AK10: 100 | AL10: 8 | AM10: 6 | AN10: 0.5 | AO10: 3 | AP10: 400
A11: F1-215 | B11: 20 | C11: 1348 | D11: 168 | E11: 320 | F11: 336 | H11: 1 | J11: 6 | K11: 8 | L11: 1 | N11: 24 | O11: 1000 | P11: 300 | Q11: 100 | R11: 100 | S11: 1 | U11: 2000 | V11: 1 | AB11: 48 | AC11: 8 | AD11: 3 | AE11: 1 | AG11: 2 | AH11: 3 | AI11: 8 | AJ11: 200 | AK11: 200 | AL11: 18 | AM11: 13 | AN11: 1 | AO11: 16
A12: F2-019 | C12: 1144 | D12: 172 | E12: 320 | F12: 312 | J12: 2 | K12: 2.5 | L12: 2 | M12: 8 | N12: 24 | O12: 1000 | P12: 600 | R12: 100 | S12: 1 | U12: 1000 | V12: 1 | X12: 480 | Y12: 150 | Z12: 900 | AB12: 48 | AC12: 4 | AE12: 1 | AH12: 3 | AI12: 8 | AJ12: 300 | AK12: 200 | AL12: 14 | AM12: 6 | AN12: 1 | AO12: 2 | AP12: 140
A13: F2-020 | B13: 10 | C13: 968 | D13: 236 | E13: 260 | F13: 312 | H13: 1 | J13: 4 | K13: 8 | L13: 1 | M13: 8 | N13: 12 | P13: 900 | Q13: 200 | R13: 100 | S13: 3 | U13: 2000 | V13: 1 | W13: 240 | X13: 780 | Y13: 150 | Z13: 270 | AB13: 60 | AC13: 8 | AE13: 2.5 | AH13: 2 | AI13: 5 | AK13: 200 | AL13: 12 | AM13: 8 | AP13: 180 | AT13: 4 | AV13: 100
A14: F2-023 | C14: 1140 | D14: 228 | E14: 270 | F14: 336 | K14: 11.5 | L14: 1 | M14: 10 | N14: 24 | O14: 500 | P14: 900 | Q14: 100 | S14: 1 | U14: 1000 | W14: 90 | X14: 780 | Y14: 180 | Z14: 450 | AB14: 72 | AC14: 4 | AD14: 3 | AE14: 2 | AF14: 25 | AH14: 2 | AI14: 5 | AK14: 200 | AL14: 14 | AM14: 5 | AN14: 0.5 | AO14: 5 | AP14: 140
A15: F2-036 | C15: 2556 | D15: 148 | E15: 600 | F15: 192 | K15: 21.5 | M15: 28 | N15: 36 | O15: 500 | P15: 1350 | Q15: 300 | R15: 200 | S15: 2 | U15: 3000 | V15: 1 | W15: 210 | X15: 2040 | Y15: 180 | Z15: 900 | AB15: 60 | AC15: 12 | AE15: 3 | AF15: 50 | AH15: 6 | AI15: 17 | AJ15: 300 | AK15: 200 | AL15: 28 | AM15: 19 | AO15: 2 | AP15: 160
A16: F2-058 | C16: 488 | D16: 128 | E16: 120 | F16: 144 | J16: 2 | K16: 1.5 | L16: 1 | M16: 10 | N16: 12 | P16: 450 | R16: 100 | S16: 1 | U16: 1000 | V16: 1 | W16: 60 | X16: 360 | Y16: 120 | Z16: 90 | AA16: 600 | AB16: 36 | AC16: 4 | AE16: 1.5 | AF16: 25 | AH16: 1 | AI16: 6 | AJ16: 300 | AK16: 100 | AL16: 4 | AM16: 3 | AN16: 1 | AO16: 7 | AP16: 140
A17: F2-144 | C17: 1080 | D17: 180 | E17: 790 | F17: 480 | J17: 4 | K17: 15 | L17: 1 | M17: 18 | N17: 24 | O17: 500 | P17: 750 | Q17: 400 | R17: 300 | S17: 2 | U17: 2000 | V17: 1 | W17: 30 | X17: 1020 | Y17: 150 | Z17: 540 | AB17: 72 | AC17: 8 | AD17: 2 | AE17: 1 | AF17: 25 | AH17: 4 | AI17: 6 | AJ17: 300 | AK17: 200 | AL17: 18 | AM17: 13 | AO17: 4 | AP17: 180 | AV17: 100
A18: F2-146 | C18: 1040 | D18: 132 | E18: 100 | F18: 72 | J18: 2 | K18: 4 | M18: 2 | N18: 12 | P18: 150 | X18: 660 | Z18: 360 | AF18: 25 | AI18: 2 | AJ18: 100 | AK18: 100 | AL18: 4 | AP18: 110
A19: F2-214 | C19: 812 | D19: 92 | E19: 70 | F19: 96 | H19: 1 | M19: 14 | O19: 1000 | P19: 300 | Q19: 100 | U19: 1000 | V19: 1 | X19: 900 | Y19: 60 | Z19: 450 | AB19: 96 | AC19: 4 | AE19: 3 | AG19: 2 | AI19: 8 | AJ19: 100 | AK19: 100 | AL19: 4 | AM19: 10 | AP19: 70 | AS19: 1
A20: F2-236 | B20: 10 | C20: 464 | D20: 60 | E20: 140 | F20: 144 | I20: 1 | J20: 2 | K20: 5 | M20: 12 | P20: 300 | S20: 0.5 | T20: 2 | X20: 300 | Y20: 60 | Z20: 270 | AB20: 36 | AH20: 1 | AI20: 3 | AL20: 8 | AM20: 3 | AO20: 3 | AP20: 50
A21: F2-283 | B21: 10 | C21: 844 | D21: 128 | E21: 350 | F21: 336 | J21: 3 | K21: 9.5 | L21: 1 | M21: 6 | O21: 500 | P21: 600 | Q21: 200 | R21: 200 | S21: 1.5 | U21: 1000 | X21: 480 | Y21: 180 | Z21: 540 | AB21: 48 | AC21: 4 | AE21: 0.5 | AF21: 25 | AH21: 2 | AI21: 6 | AJ21: 100 | AK21: 100 | AL21: 10 | AM21: 5 | AN21: 0.5 | AO21: 1 | AP21: 150
A22: F3-026 | C22: 1456 | D22: 164 | E22: 430 | F22: 312 | K22: 11 | L22: 1 | M22: 4 | N22: 24 | P22: 900 | Q22: 200 | R22: 100 | S22: 0.5 | U22: 2000 | X22: 1080 | Y22: 150 | Z22: 270 | AB22: 24 | AC22: 4 | AF22: 25 | AG22: 1 | AH22: 4 | AI22: 8 | AJ22: 100 | AK22: 100 | AL22: 12 | AM22: 5 | AP22: 160 | AS22: 3
A23: F3-027 | C23: 384 | D23: 60 | E23: 140 | F23: 96 | K23: 6 | L23: 1 | M23: 6 | N23: 12 | P23: 300 | R23: 100 | S23: 0.5 | X23: 240 | Y23: 90 | Z23: 270 | AB23: 36 | AF23: 25 | AH23: 2 | AI23: 4 | AJ23: 100 | AK23: 100 | AL23: 6 | AM23: 2 | AO23: 1 | AP23: 60
A24: F3-028 | C24: 680 | D24: 52 | E24: 180 | F24: 120 | K24: 6 | M24: 8 | N24: 12 | P24: 600 | Q24: 100 | R24: 100 | S24: 0.5 | U24: 1000 | X24: 480 | Y24: 90 | Z24: 360 | AB24: 24 | AC24: 4 | AH24: 3 | AI24: 4 | AJ24: 200 | AL24: 8 | AM24: 2 | AO24: 4 | AP24: 60
A25: F3-029 | C25: 1436 | D25: 176 | E25: 410 | F25: 360 | K25: 12 | L25: 2 | M25: 12 | N25: 12 | O25: 500 | P25: 1050 | Q25: 300 | R25: 200 | S25: 1 | U25: 2000 | V25: 1 | X25: 1140 | Y25: 210 | Z25: 540 | AB25: 72 | AC25: 8 | AD25: 2 | AF25: 25 | AH25: 3 | AI25: 10 | AJ25: 200 | AK25: 200 | AL25: 18 | AM25: 6 | AO25: 2 | AP25: 180
A26: F3-030 | C26: 828 | D26: 76 | E26: 210 | F26: 336 | J26: 1 | K26: 4 | L26: 1 | M26: 6 | P26: 600 | R26: 100 | S26: 1 | U26: 1000 | X26: 600 | Y26: 90 | Z26: 360 | AB26: 36 | AC26: 4 | AF26: 25 | AH26: 2 | AI26: 6 | AJ26: 100 | AK26: 100 | AL26: 8 | AM26: 5 | AO26: 8 | AP26: 110 | AT26: 1 | AV26: 100
A27: F3-044 | B27: 10 | C27: 1480 | D27: 176 | E27: 340 | F27: 480 | J27: 6 | K27: 26 | L27: 1 | M27: 22 | N27: 24 | O27: 1000 | P27: 1050 | Q27: 200 | R27: 300 | S27: 4 | U27: 3000 | V27: 1 | W27: 60 | X27: 1140 | Y27: 240 | Z27: 720 | AA27: 100 | AB27: 108 | AC27: 12 | AD27: 3 | AE27: 1.5 | AF27: 75 | AH27: 3 | AI27: 10 | AJ27: 100 | AK27: 300 | AL27: 20 | AM27: 11 | AN27: 0.5 | AO27: 10 | AP27: 160 | AV27: 100
A28: F3-097 | B28: 10 | C28: 1956 | D28: 368 | E28: 350 | F28: 624 | J28: 3 | K28: 2 | L28: 2 | M28: 16 | N28: 48 | O28: 500 | P28: 1200 | R28: 300 | S28: 3 | U28: 3000 | V28: 1 | X28: 1680 | Y28: 150 | Z28: 630 | AB28: 60 | AC28: 12 | AD28: 5 | AE28: 3 | AF28: 25 | AH28: 5 | AI28: 14 | AJ28: 300 | AK28: 300 | AL28: 18 | AM28: 6 | AN28: 1 | AP28: 330 | AV28: 100
A29: F3-112 | C29: 1800 | D29: 128 | E29: 120 | F29: 96 | J29: 5 | K29: 7 | L29: 1 | M29: 12 | N29: 12 | O29: 500 | P29: 1200 | S29: 0.5 | T29: 1 | U29: 2000 | V29: 1 | X29: 1200 | Y29: 120 | Z29: 720 | AA29: 100 | AB29: 120 | AC29: 8 | AH29: 1 | AI29: 8 | AJ29: 100 | AK29: 200 | AL29: 12 | AM29: 7 | AO29: 1 | AP29: 130
A30: F3-122 | C30: 820 | D30: 84 | E30: 140 | F30: 96 | J30: 2 | K30: 8 | M30: 16 | O30: 500 | P30: 600 | R30: 100 | U30: 1000 | V30: 1 | X30: 660 | Y30: 90 | Z30: 180 | AB30: 12 | AC30: 4 | AE30: 0.5 | AH30: 2 | AI30: 5 | AJ30: 100 | AK30: 100 | AL30: 8 | AM30: 7 | AO30: 5 | AP30: 90
A31: F3-150 | C31: 720 | D31: 80 | E31: 60 | F31: 168 | M31: 10 | N31: 12 | O31: 500 | P31: 600 | Q31: 100 | R31: 100 | S31: 1 | U31: 1000 | V31: 1 | W31: 30 | X31: 600 | Y31: 120 | Z31: 180 | AA31: 100 | AB31: 72 | AC31: 4 | AD31: 1 | AE31: 1 | AH31: 1 | AI31: 4 | AK31: 100 | AL31: 10 | AM31: 3 | AN31: 0.5 | AO31: 1 | AP31: 90
A32: F3-157 | B32: 30 | C32: 3672 | D32: 696 | E32: 210 | F32: 408 | K32: 6 | L32: 2 | M32: 12 | N32: 48 | O32: 1500 | P32: 2400 | R32: 300 | S32: 3.5 | U32: 2000 | W32: 90 | X32: 2880 | Y32: 240 | Z32: 1080 | AB32: 36 | AC32: 8 | AD32: 1 | AE32: 1.5 | AF32: 25 | AH32: 3 | AI32: 5 | AJ32: 100 | AK32: 700 | AL32: 6 | AM32: 18 | AO32: 2 | AP32: 740 | AS32: 5 | AV32: 100
A33: F3-159 | C33: 980 | D33: 60 | E33: 50 | H33: 1 | M33: 14 | N33: 12 | P33: 750 | U33: 1000 | X33: 780 | Y33: 90 | Z33: 270 | AA33: 100 | AB33: 84 | AC33: 4 | AE33: 0.5 | AF33: 25 | AH33: 1 | AI33: 4 | AK33: 100 | AL33: 8 | AM33: 3 | AO33: 1 | AP33: 50
A34: F3-180 | C34: 916 | D34: 104 | E34: 150 | F34: 168 | J34: 4 | K34: 12 | M34: 10 | N34: 12 | O34: 500 | P34: 750 | Q34: 100 | S34: 0.5 | U34: 1000 | X34: 720 | Y34: 150 | Z34: 270 | AB34: 36 | AC34: 4 | AD34: 1 | AE34: 0.5 | AH34: 1 | AI34: 4 | AK34: 100 | AL34: 8 | AM34: 4 | AN34: 0.5 | AP34: 110 | AS34: 1
A35: F3-192 | C35: 588 | D35: 52 | E35: 220 | F35: 144 | J35: 2 | K35: 11 | M35: 6 | O35: 500 | P35: 300 | Q35: 100 | S35: 0.5 | X35: 300 | Y35: 180 | Z35: 270 | AB35: 12 | AE35: 1.5 | AH35: 1 | AI35: 3 | AJ35: 100 | AL35: 8 | AM35: 11 | AN35: 0.5 | AP35: 50
A36: F3-200 | C36: 1224 | D36: 176 | E36: 160 | F36: 336 | K36: 2 | M36: 18 | P36: 600 | U36: 2000 | V36: 1 | X36: 780 | Y36: 90 | Z36: 90 | AB36: 48 | AC36: 8 | AE36: 2.5 | AG36: 3 | AI36: 5 | AK36: 200 | AL36: 4 | AM36: 9 | AO36: 1 | AP36: 110 | AS36: 2
A37: F3-210 | B37: 10 | C37: 2152 | D37: 380 | E37: 130 | F37: 192 | I37: 1 | K37: 16 | L37: 1 | M37: 32 | N37: 24 | O37: 500 | P37: 1650 | Q37: 100 | S37: 1.5 | T37: 2 | U37: 2000 | V37: 2 | X37: 1740 | Y37: 120 | Z37: 630 | AB37: 108 | AC37: 8 | AD37: 1 | AE37: 0.5 | AF37: 25 | AH37: 3 | AI37: 14 | AK37: 400 | AL37: 18 | AM37: 6 | AO37: 1 | AP37: 360
A38: F3-224 | C38: 704 | D38: 72 | E38: 140 | F38: 144 | K38: 12 | L38: 1 | M38: 12 | N38: 12 | P38: 600 | Q38: 100 | R38: 100 | S38: 0.5 | U38: 1000 | V38: 1 | X38: 660 | Y38: 120 | Z38: 270 | AB38: 24 | AC38: 4 | AH38: 4 | AI38: 9 | AK38: 100 | AL38: 8 | AM38: 3 | AO38: 1 | AP38: 90
A39: F3-227 | C39: 1040 | D39: 132 | E39: 270 | F39: 312 | J39: 6 | K39: 11 | L39: 2 | M39: 24 | O39: 500 | P39: 600 | R39: 300 | S39: 2 | U39: 1000 | X39: 660 | Y39: 240 | Z39: 450 | AB39: 72 | AC39: 4 | AE39: 1.5 | AF39: 25 | AH39: 1 | AI39: 6 | AJ39: 300 | AK39: 100 | AL39: 12 | AM39: 4 | AO39: 23 | AP39: 110
A40: F3-228 | B40: 10 | C40: 1828 | D40: 136 | E40: 350 | F40: 144 | K40: 8 | L40: 1 | M40: 32 | N40: 24 | O40: 500 | P40: 1350 | Q40: 200 | S40: 1 | U40: 2000 | V40: 1 | X40: 1380 | Y40: 150 | Z40: 450 | AB40: 72 | AC40: 8 | AD40: 1 | AH40: 3 | AI40: 6 | AK40: 100 | AL40: 10 | AM40: 10 | AO40: 3 | AP40: 250
...

Sheet ChiTiet
E1: =ISTEXT(G1) -> FALSE | F1: 1001 | G1: 1004 | H1: 1003 | I1: 1002 | J1: 1201 | K1: 1200 | L1: 1205 | M1: 1234 | N1: 1204 | O1: 1208 | P1: 1403 | Q1: 1405 | R1: 1401 | S1: 1209 | T1: 1421 | U1: 1402 | V1: 1102 | W1: 1101 | X1: 1109 | Y1: 1103 | Z1: 1104 | AA1: 2008 | AB1: 2017 | AC1: 2021 | AD1: 2064 | AE1: 2019 | AF1: 2027 | AG1: 2068 | AH1: 2012 | AI1: 2066 | AJ1: 2067 | AK1: 1203 | AL1: 1214
E2: Cột tham chiếu | F2: 3 | G2: 4 | H2: 5 | I2: 6 | J2: 26 | K2: 24 | L2: 42 | M2: 30 | N2: 12 | O2: 19 | P2: 32 | Q2: 34 | R2: 11 | S2: 28 | T2: 10 | U2: 14 | V2: 38 | W2: 39 | X2: 40 | Y2: 41 | Z2: 13 | AA2: 15 | AB2: 16 | AC2: 17 | AD2: 18 | AE2: 36 | AF2: 37 | AG2: 21 | AH2: 22 | AI2: 29 | AJ2: 35 | AK2: 25 | AL2: 23 | AM2: 31 | AN2: 8 | AO2: 27
B3: MÃ NQ | C3: Quản lý | D3: Mã NQ | E3: NHƯỢNG QUYỀN | F3: Bánh mì hamburger | G3: Bánh Mì Hotdog | H3: Bánh mì pita | I3: Bánh mì sandwich | J3: Thịt hamburger (90m/thùng ) | K3: Hamburger Gà (60 miếng / thùng) | L3: Xúc Xích ( 10 cây / 0.5kg) | M3: Pate gan (0.5 kg / bịch) | N3: Chà bông xốp ( 1kg/bịch) | O3: Jam Bon đặt biệt ( 250g/bịch) | P3: Sữa bột 25kg/bịch) | Q3: Trà Đen (1kg/ bich) | R3: Bột Kem Sữa Cacao kg | S3: Nước Ngọt pesi 1.5 lit / chai (12 chai/ thùng) | T3: Bột chanh (1kg/túi) | U3: Đường trắng (12kg/bao) | V3: Tương cà lớn (2Lit/Bình) | W3: Tương Mayonaise ( 1kg/bịch) | X3: Tương mù tạc (0.5kg/ bịch) | Y3: Tương ớt Cholimex (270gram/chai) | Z3: Dầu ăn ( 2 lit/bình ) | AA3: Giấy gói bánh mì ( 500 tờ/xấp) | AB3: Hộp Giấy Buger Gà (150 cái/ thùng) | AC3: Hộp Giấy Pita Gà (100 cái/ xấp) | AD3: Hộp Giấy Sanwich (100 cái/ xấp) | AE3: Túi Giấy Đựng Pita (100 cái/ xấp) | AF3: Túi Giấy Hotdog (100 cái/ xấp) | AG3: Ly giấy in logo 1p30s (1000 cái/thùng) | AH3: Màng ép ly 1p30s ( 3600ly/ cuộn) | AI3: ống hút Giấy đầu nhọn (250 cây/ bao) | AJ3: Túi dựng ly 1p30s ( 192 cái / kg) | AK3: Miếng thịt burger Tôm (30 miếng/thùng) | AL3: Miếng thịt bò hỗn hợp (30 miếng/thùng) | AM3: Sốt Phô Mai (0.5kg/túi) | AN3: Bao Tay xốp | AO3: Nắp ly nhựa phi 90 ( 50 cái/ bao)
A4: Duc Hoa | C4: Cường | D4: F1-115 | E4: Tiệm ăn sáng NQ Phước Kiểng 1 (Trạm CH) | F4: =_xlfn.IFNA(VLOOKUP($D4,Dulieutho,F$2,FALSE),"") -> 492 | G4: =_xlfn.IFNA(VLOOKUP($D4,Dulieutho,G$2,FALSE),"") -> 92 | H4: =_xlfn.IFNA(VLOOKUP($D4,Dulieutho,H$2,FALSE),"") -> 70 | I4: =_xlfn.IFNA(VLOOKUP($D4,Dulieutho,I$2,FALSE),"") -> 144 | J4: =_xlfn.IFNA(VLOOKUP($D4,Dulieutho,J$2,FALSE),"") -> 270 | K4: =_xlfn.IFNA(VLOOKUP($D4,Dulieutho,K$2,FALSE),"") -> 240 | L4: =_xlfn.IFNA(VLOOKUP($D4,Dulieutho,L$2,FALSE),"") -> 70 | M4: =_xlfn.IFNA(VLOOKUP($D4,Dulieutho,M$2,FALSE),"") -> 0 | ... AO4: =_xlfn.IFNA(VLOOKUP($D4,Dulieutho,AO$2,FALSE),"") -> 600
C5: Cường | D5: F5-149 | E5: Tiệm ăn sáng NQ Âu Dương Lân (Trạm Chánh Hưng) | F5: =_xlfn.IFNA(VLOOKUP($D5,Dulieutho,F$2,FALSE),"") | G5: =_xlfn.IFNA(VLOOKUP($D5,Dulieutho,G$2,FALSE),"") | H5: =_xlfn.IFNA(VLOOKUP($D5,Dulieutho,H$2,FALSE),"") | I5: =_xlfn.IFNA(VLOOKUP($D5,Dulieutho,I$2,FALSE),"") | J5: =_xlfn.IFNA(VLOOKUP($D5,Dulieutho,J$2,FALSE),"") | K5: =_xlfn.IFNA(VLOOKUP($D5,Dulieutho,K$2,FALSE),"") | L5: =_xlfn.IFNA(VLOOKUP($D5,Dulieutho,L$2,FALSE),"") | M5: =_xlfn.IFNA(VLOOKUP($D5,Dulieutho,M$2,FALSE),"") | ... AO5: =_xlfn.IFNA(VLOOKUP($D5,Dulieutho,AO$2,FALSE),"")
A6: Hau Nghia | C6: Cường | D6: F6-260 | E6: Tiệm ăn sáng NQ Cô Giang 1 (Trạm SVH) | F6: =_xlfn.IFNA(VLOOKUP($D6,Dulieutho,F$2,FALSE),"") -> 360 | G6: =_xlfn.IFNA(VLOOKUP($D6,Dulieutho,G$2,FALSE),"") -> 56 | H6: =_xlfn.IFNA(VLOOKUP($D6,Dulieutho,H$2,FALSE),"") -> 150 | I6: =_xlfn.IFNA(VLOOKUP($D6,Dulieutho,I$2,FALSE),"") -> 0 | J6: =_xlfn.IFNA(VLOOKUP($D6,Dulieutho,J$2,FALSE),"") -> 0 | K6: =_xlfn.IFNA(VLOOKUP($D6,Dulieutho,K$2,FALSE),"") -> 0 | L6: =_xlfn.IFNA(VLOOKUP($D6,Dulieutho,L$2,FALSE),"") -> 0 | M6: =_xlfn.IFNA(VLOOKUP($D6,Dulieutho,M$2,FALSE),"") -> 0 | ... AO6: =_xlfn.IFNA(VLOOKUP($D6,Dulieutho,AO$2,FALSE),"") -> 0
A7: Can Giuoc | C7: Cường | D7: F3-041 | E7: Tiệm ăn sáng NQ Đinh Tiên Hoàng (Trạm SVH) | F7: =_xlfn.IFNA(VLOOKUP($D7,Dulieutho,F$2,FALSE),"") | G7: =_xlfn.IFNA(VLOOKUP($D7,Dulieutho,G$2,FALSE),"") | H7: =_xlfn.IFNA(VLOOKUP($D7,Dulieutho,H$2,FALSE),"") | I7: =_xlfn.IFNA(VLOOKUP($D7,Dulieutho,I$2,FALSE),"") | J7: =_xlfn.IFNA(VLOOKUP($D7,Dulieutho,J$2,FALSE),"") | K7: =_xlfn.IFNA(VLOOKUP($D7,Dulieutho,K$2,FALSE),"") | L7: =_xlfn.IFNA(VLOOKUP($D7,Dulieutho,L$2,FALSE),"") | M7: =_xlfn.IFNA(VLOOKUP($D7,Dulieutho,M$2,FALSE),"") | ... AO7: =_xlfn.IFNA(VLOOKUP($D7,Dulieutho,AO$2,FALSE),"")
A8: Tan An | C8: Cường | D8: F5-096 | E8: Tiệm ăn sáng NQ Đồng Nai (Trạm SVH) | F8: =_xlfn.IFNA(VLOOKUP($D8,Dulieutho,F$2,FALSE),"") -> 1912 | G8: =_xlfn.IFNA(VLOOKUP($D8,Dulieutho,G$2,FALSE),"") -> 144 | H8: =_xlfn.IFNA(VLOOKUP($D8,Dulieutho,H$2,FALSE),"") -> 880 | I8: =_xlfn.IFNA(VLOOKUP($D8,Dulieutho,I$2,FALSE),"") -> 360 | J8: =_xlfn.IFNA(VLOOKUP($D8,Dulieutho,J$2,FALSE),"") -> 630 | K8: =_xlfn.IFNA(VLOOKUP($D8,Dulieutho,K$2,FALSE),"") -> 1740 | L8: =_xlfn.IFNA(VLOOKUP($D8,Dulieutho,L$2,FALSE),"") -> 250 | M8: =_xlfn.IFNA(VLOOKUP($D8,Dulieutho,M$2,FALSE),"") -> 2 | ... AO8: =_xlfn.IFNA(VLOOKUP($D8,Dulieutho,AO$2,FALSE),"") -> 0
A9: Vinh Kim | C9: Cường | D9: F7-235 | E9: Tiệm ăn sáng NQ Hóc Môn (Trạm Tân Phú) | F9: =_xlfn.IFNA(VLOOKUP($D9,Dulieutho,F$2,FALSE),"") -> 2216 | G9: =_xlfn.IFNA(VLOOKUP($D9,Dulieutho,G$2,FALSE),"") -> 232 | H9: =_xlfn.IFNA(VLOOKUP($D9,Dulieutho,H$2,FALSE),"") -> 210 | I9: =_xlfn.IFNA(VLOOKUP($D9,Dulieutho,I$2,FALSE),"") -> 120 | J9: =_xlfn.IFNA(VLOOKUP($D9,Dulieutho,J$2,FALSE),"") -> 630 | K9: =_xlfn.IFNA(VLOOKUP($D9,Dulieutho,K$2,FALSE),"") -> 1680 | L9: =_xlfn.IFNA(VLOOKUP($D9,Dulieutho,L$2,FALSE),"") -> 1460 | M9: =_xlfn.IFNA(VLOOKUP($D9,Dulieutho,M$2,FALSE),"") -> 1 | ... AO9: =_xlfn.IFNA(VLOOKUP($D9,Dulieutho,AO$2,FALSE),"") -> 0
C10: Cường | D10: F1-184 | E10: Tiệm ăn sáng NQ Huỳnh Tấn Phát (Trạm Chánh Hưng) | F10: =_xlfn.IFNA(VLOOKUP($D10,Dulieutho,F$2,FALSE),"") -> 3480 | G10: =_xlfn.IFNA(VLOOKUP($D10,Dulieutho,G$2,FALSE),"") -> 656 | H10: =_xlfn.IFNA(VLOOKUP($D10,Dulieutho,H$2,FALSE),"") -> 500 | I10: =_xlfn.IFNA(VLOOKUP($D10,Dulieutho,I$2,FALSE),"") -> 816 | J10: =_xlfn.IFNA(VLOOKUP($D10,Dulieutho,J$2,FALSE),"") -> 1440 | K10: =_xlfn.IFNA(VLOOKUP($D10,Dulieutho,K$2,FALSE),"") -> 2520 | L10: =_xlfn.IFNA(VLOOKUP($D10,Dulieutho,L$2,FALSE),"") -> 400 | M10: =_xlfn.IFNA(VLOOKUP($D10,Dulieutho,M$2,FALSE),"") -> 1 | ... AO10: =_xlfn.IFNA(VLOOKUP($D10,Dulieutho,AO$2,FALSE),"") -> 0
A11: Hung Vuong | C11: Cường | D11: F2-036 | E11: Tiệm ăn sáng NQ Huỳnh Tịnh Của (Trạm SVH) | F11: =_xlfn.IFNA(VLOOKUP($D11,Dulieutho,F$2,FALSE),"") -> 2556 | G11: =_xlfn.IFNA(VLOOKUP($D11,Dulieutho,G$2,FALSE),"") -> 148 | H11: =_xlfn.IFNA(VLOOKUP($D11,Dulieutho,H$2,FALSE),"") -> 600 | I11: =_xlfn.IFNA(VLOOKUP($D11,Dulieutho,I$2,FALSE),"") -> 192 | J11: =_xlfn.IFNA(VLOOKUP($D11,Dulieutho,J$2,FALSE),"") -> 900 | K11: =_xlfn.IFNA(VLOOKUP($D11,Dulieutho,K$2,FALSE),"") -> 2040 | L11: =_xlfn.IFNA(VLOOKUP($D11,Dulieutho,L$2,FALSE),"") -> 160 | M11: =_xlfn.IFNA(VLOOKUP($D11,Dulieutho,M$2,FALSE),"") -> 0 | ... AO11: =_xlfn.IFNA(VLOOKUP($D11,Dulieutho,AO$2,FALSE),"") -> 0
A12: Bac Lieu | C12: Cường | D12: F6-071 | E12: Tiệm ăn sáng NQ Kỳ Đồng (Trạm SVH) | F12: =_xlfn.IFNA(VLOOKUP($D12,Dulieutho,F$2,FALSE),"") -> 628 | G12: =_xlfn.IFNA(VLOOKUP($D12,Dulieutho,G$2,FALSE),"") -> 136 | H12: =_xlfn.IFNA(VLOOKUP($D12,Dulieutho,H$2,FALSE),"") -> 270 | I12: =_xlfn.IFNA(VLOOKUP($D12,Dulieutho,I$2,FALSE),"") -> 264 | J12: =_xlfn.IFNA(VLOOKUP($D12,Dulieutho,J$2,FALSE),"") -> 270 | K12: =_xlfn.IFNA(VLOOKUP($D12,Dulieutho,K$2,FALSE),"") -> 660 | L12: =_xlfn.IFNA(VLOOKUP($D12,Dulieutho,L$2,FALSE),"") -> 120 | M12: =_xlfn.IFNA(VLOOKUP($D12,Dulieutho,M$2,FALSE),"") -> 1 | ... AO12: =_xlfn.IFNA(VLOOKUP($D12,Dulieutho,AO$2,FALSE),"") -> 0
A13: Chau Doc | C13: Cường | D13: F1-215 | E13: Tiệm ăn sáng NQ Lâm Văn Bền (Trạm Chánh Hưng) | F13: =_xlfn.IFNA(VLOOKUP($D13,Dulieutho,F$2,FALSE),"") -> 1348 | G13: =_xlfn.IFNA(VLOOKUP($D13,Dulieutho,G$2,FALSE),"") -> 168 | H13: =_xlfn.IFNA(VLOOKUP($D13,Dulieutho,H$2,FALSE),"") -> 320 | I13: =_xlfn.IFNA(VLOOKUP($D13,Dulieutho,I$2,FALSE),"") -> 336 | J13: =_xlfn.IFNA(VLOOKUP($D13,Dulieutho,J$2,FALSE),"") -> 0 | K13: =_xlfn.IFNA(VLOOKUP($D13,Dulieutho,K$2,FALSE),"") -> 0 | L13: =_xlfn.IFNA(VLOOKUP($D13,Dulieutho,L$2,FALSE),"") -> 0 | M13: =_xlfn.IFNA(VLOOKUP($D13,Dulieutho,M$2,FALSE),"") -> 3 | ... AO13: =_xlfn.IFNA(VLOOKUP($D13,Dulieutho,AO$2,FALSE),"") -> 0
A14: Go Dau | C14: Cường | D14: F1-191 | E14: Tiệm ăn sáng NQ Lê Thánh Tôn (Trạm Chánh Hưng) | F14: =_xlfn.IFNA(VLOOKUP($D14,Dulieutho,F$2,FALSE),"") -> 1152 | G14: =_xlfn.IFNA(VLOOKUP($D14,Dulieutho,G$2,FALSE),"") -> 148 | H14: =_xlfn.IFNA(VLOOKUP($D14,Dulieutho,H$2,FALSE),"") -> 350 | I14: =_xlfn.IFNA(VLOOKUP($D14,Dulieutho,I$2,FALSE),"") -> 360 | J14: =_xlfn.IFNA(VLOOKUP($D14,Dulieutho,J$2,FALSE),"") -> 540 | K14: =_xlfn.IFNA(VLOOKUP($D14,Dulieutho,K$2,FALSE),"") -> 900 | L14: =_xlfn.IFNA(VLOOKUP($D14,Dulieutho,L$2,FALSE),"") -> 230 | M14: =_xlfn.IFNA(VLOOKUP($D14,Dulieutho,M$2,FALSE),"") -> 3 | ... AO14: =_xlfn.IFNA(VLOOKUP($D14,Dulieutho,AO$2,FALSE),"") -> 0
A15: Vung Tau | C15: Cường | D15: F6-145 | E15: Tiệm ăn sáng NQ Lương Đình Của (Trạm Thủ Đức) | F15: =_xlfn.IFNA(VLOOKUP($D15,Dulieutho,F$2,FALSE),"") -> 900 | G15: =_xlfn.IFNA(VLOOKUP($D15,Dulieutho,G$2,FALSE),"") -> 160 | H15: =_xlfn.IFNA(VLOOKUP($D15,Dulieutho,H$2,FALSE),"") -> 140 | I15: =_xlfn.IFNA(VLOOKUP($D15,Dulieutho,I$2,FALSE),"") -> 264 | J15: =_xlfn.IFNA(VLOOKUP($D15,Dulieutho,J$2,FALSE),"") -> 360 | K15: =_xlfn.IFNA(VLOOKUP($D15,Dulieutho,K$2,FALSE),"") -> 540 | L15: =_xlfn.IFNA(VLOOKUP($D15,Dulieutho,L$2,FALSE),"") -> 160 | M15: =_xlfn.IFNA(VLOOKUP($D15,Dulieutho,M$2,FALSE),"") -> 1 | ... AO15: =_xlfn.IFNA(VLOOKUP($D15,Dulieutho,AO$2,FALSE),"") -> 0
A16: Nguyen Khuyen | C16: Cường | D16: F5-092 | E16: Tiệm ăn sáng NQ Nguyễn ảnh Thủ (Trạm GV) | F16: =_xlfn.IFNA(VLOOKUP($D16,Dulieutho,F$2,FALSE),"") -> 1060 | G16: =_xlfn.IFNA(VLOOKUP($D16,Dulieutho,G$2,FALSE),"") -> 240 | H16: =_xlfn.IFNA(VLOOKUP($D16,Dulieutho,H$2,FALSE),"") -> 240 | I16: =_xlfn.IFNA(VLOOKUP($D16,Dulieutho,I$2,FALSE),"") -> 552 | J16: =_xlfn.IFNA(VLOOKUP($D16,Dulieutho,J$2,FALSE),"") -> 540 | K16: =_xlfn.IFNA(VLOOKUP($D16,Dulieutho,K$2,FALSE),"") -> 660 | L16: =_xlfn.IFNA(VLOOKUP($D16,Dulieutho,L$2,FALSE),"") -> 260 | M16: =_xlfn.IFNA(VLOOKUP($D16,Dulieutho,M$2,FALSE),"") -> 4 | ... AO16: =_xlfn.IFNA(VLOOKUP($D16,Dulieutho,AO$2,FALSE),"") -> 0
A17: Binh Da | C17: Cường | D17: F2-146 | E17: Tiệm ăn sáng NQ Lê Trọng Tấn (Trạm Tân Phú) | F17: =_xlfn.IFNA(VLOOKUP($D17,Dulieutho,F$2,FALSE),"") -> 1040 | G17: =_xlfn.IFNA(VLOOKUP($D17,Dulieutho,G$2,FALSE),"") -> 132 | H17: =_xlfn.IFNA(VLOOKUP($D17,Dulieutho,H$2,FALSE),"") -> 100 | I17: =_xlfn.IFNA(VLOOKUP($D17,Dulieutho,I$2,FALSE),"") -> 72 | J17: =_xlfn.IFNA(VLOOKUP($D17,Dulieutho,J$2,FALSE),"") -> 360 | K17: =_xlfn.IFNA(VLOOKUP($D17,Dulieutho,K$2,FALSE),"") -> 660 | L17: =_xlfn.IFNA(VLOOKUP($D17,Dulieutho,L$2,FALSE),"") -> 110 | M17: =_xlfn.IFNA(VLOOKUP($D17,Dulieutho,M$2,FALSE),"") -> 0 | ... AO17: =_xlfn.IFNA(VLOOKUP($D17,Dulieutho,AO$2,FALSE),"") -> 0
A18: Long Thanh | C18: Cường | D18: F3-192 | E18: Tiệm ăn sáng NQ Nguyễn Đình Chiểu (Trạm SVH) | F18: =_xlfn.IFNA(VLOOKUP($D18,Dulieutho,F$2,FALSE),"") -> 588 | G18: =_xlfn.IFNA(VLOOKUP($D18,Dulieutho,G$2,FALSE),"") -> 52 | H18: =_xlfn.IFNA(VLOOKUP($D18,Dulieutho,H$2,FALSE),"") -> 220 | I18: =_xlfn.IFNA(VLOOKUP($D18,Dulieutho,I$2,FALSE),"") -> 144 | J18: =_xlfn.IFNA(VLOOKUP($D18,Dulieutho,J$2,FALSE),"") -> 270 | K18: =_xlfn.IFNA(VLOOKUP($D18,Dulieutho,K$2,FALSE),"") -> 300 | L18: =_xlfn.IFNA(VLOOKUP($D18,Dulieutho,L$2,FALSE),"") -> 50 | M18: =_xlfn.IFNA(VLOOKUP($D18,Dulieutho,M$2,FALSE),"") -> 0 | ... AO18: =_xlfn.IFNA(VLOOKUP($D18,Dulieutho,AO$2,FALSE),"") -> 0
A19: Binh Chuan | C19: Cường | D19: F6-082 | E19: Tiệm ăn sáng NQ Nguyễn Duy Trinh (Trạm Thủ Đức) | F19: =_xlfn.IFNA(VLOOKUP($D19,Dulieutho,F$2,FALSE),"") -> 2688 | G19: =_xlfn.IFNA(VLOOKUP($D19,Dulieutho,G$2,FALSE),"") -> 412 | H19: =_xlfn.IFNA(VLOOKUP($D19,Dulieutho,H$2,FALSE),"") -> 700 | I19: =_xlfn.IFNA(VLOOKUP($D19,Dulieutho,I$2,FALSE),"") -> 600 | J19: =_xlfn.IFNA(VLOOKUP($D19,Dulieutho,J$2,FALSE),"") -> 1440 | K19: =_xlfn.IFNA(VLOOKUP($D19,Dulieutho,K$2,FALSE),"") -> 1980 | L19: =_xlfn.IFNA(VLOOKUP($D19,Dulieutho,L$2,FALSE),"") -> 410 | M19: =_xlfn.IFNA(VLOOKUP($D19,Dulieutho,M$2,FALSE),"") -> 3 | ... AO19: =_xlfn.IFNA(VLOOKUP($D19,Dulieutho,AO$2,FALSE),"") -> 0
A20: An Binh | C20: Cường | D20: F1-022 | E20: Tiệm ăn sáng NQ Nguyễn Khoái (Trạm CH) | F20: =_xlfn.IFNA(VLOOKUP($D20,Dulieutho,F$2,FALSE),"") -> 888 | G20: =_xlfn.IFNA(VLOOKUP($D20,Dulieutho,G$2,FALSE),"") -> 268 | H20: =_xlfn.IFNA(VLOOKUP($D20,Dulieutho,H$2,FALSE),"") -> 230 | I20: =_xlfn.IFNA(VLOOKUP($D20,Dulieutho,I$2,FALSE),"") -> 384 | J20: =_xlfn.IFNA(VLOOKUP($D20,Dulieutho,J$2,FALSE),"") -> 0 | K20: =_xlfn.IFNA(VLOOKUP($D20,Dulieutho,K$2,FALSE),"") -> 60 | L20: =_xlfn.IFNA(VLOOKUP($D20,Dulieutho,L$2,FALSE),"") -> 220 | M20: =_xlfn.IFNA(VLOOKUP($D20,Dulieutho,M$2,FALSE),"") -> 0 | ... AO20: =_xlfn.IFNA(VLOOKUP($D20,Dulieutho,AO$2,FALSE),"") -> 1500
C21: Cường | D21: F6-258 | E21: Tiệm ăn sáng NQ Nguyễn Thị Định (Trạm Thủ Đức) | F21: =_xlfn.IFNA(VLOOKUP($D21,Dulieutho,F$2,FALSE),"") -> 1136 | G21: =_xlfn.IFNA(VLOOKUP($D21,Dulieutho,G$2,FALSE),"") -> 212 | H21: =_xlfn.IFNA(VLOOKUP($D21,Dulieutho,H$2,FALSE),"") -> 220 | I21: =_xlfn.IFNA(VLOOKUP($D21,Dulieutho,I$2,FALSE),"") -> 240 | J21: =_xlfn.IFNA(VLOOKUP($D21,Dulieutho,J$2,FALSE),"") -> 720 | K21: =_xlfn.IFNA(VLOOKUP($D21,Dulieutho,K$2,FALSE),"") -> 840 | L21: =_xlfn.IFNA(VLOOKUP($D21,Dulieutho,L$2,FALSE),"") -> 190 | M21: =_xlfn.IFNA(VLOOKUP($D21,Dulieutho,M$2,FALSE),"") -> 0 | ... AO21: =_xlfn.IFNA(VLOOKUP($D21,Dulieutho,AO$2,FALSE),"") -> 0
C22: Cường | D22: F3-273 | E22: Tiệm ăn sáng NQ Lý Thái Tổ (Trạm SVH) | F22: =_xlfn.IFNA(VLOOKUP($D22,Dulieutho,F$2,FALSE),"") -> 832 | G22: =_xlfn.IFNA(VLOOKUP($D22,Dulieutho,G$2,FALSE),"") -> 124 | H22: =_xlfn.IFNA(VLOOKUP($D22,Dulieutho,H$2,FALSE),"") -> 430 | I22: =_xlfn.IFNA(VLOOKUP($D22,Dulieutho,I$2,FALSE),"") -> 240 | J22: =_xlfn.IFNA(VLOOKUP($D22,Dulieutho,J$2,FALSE),"") -> 450 | K22: =_xlfn.IFNA(VLOOKUP($D22,Dulieutho,K$2,FALSE),"") -> 660 | L22: =_xlfn.IFNA(VLOOKUP($D22,Dulieutho,L$2,FALSE),"") -> 130 | M22: =_xlfn.IFNA(VLOOKUP($D22,Dulieutho,M$2,FALSE),"") -> 0 | ... AO22: =_xlfn.IFNA(VLOOKUP($D22,Dulieutho,AO$2,FALSE),"") -> 0
C23: Cường | D23: F2-214 | E23: Tiệm ăn sáng NQ Nhà Bè (Trạm Chánh Hưng) | F23: =_xlfn.IFNA(VLOOKUP($D23,Dulieutho,F$2,FALSE),"") -> 812 | G23: =_xlfn.IFNA(VLOOKUP($D23,Dulieutho,G$2,FALSE),"") -> 92 | H23: =_xlfn.IFNA(VLOOKUP($D23,Dulieutho,H$2,FALSE),"") -> 70 | I23: =_xlfn.IFNA(VLOOKUP($D23,Dulieutho,I$2,FALSE),"") -> 96 | J23: =_xlfn.IFNA(VLOOKUP($D23,Dulieutho,J$2,FALSE),"") -> 450 | K23: =_xlfn.IFNA(VLOOKUP($D23,Dulieutho,K$2,FALSE),"") -> 900 | L23: =_xlfn.IFNA(VLOOKUP($D23,Dulieutho,L$2,FALSE),"") -> 70 | M23: =_xlfn.IFNA(VLOOKUP($D23,Dulieutho,M$2,FALSE),"") -> 0 | ... AO23: =_xlfn.IFNA(VLOOKUP($D23,Dulieutho,AO$2,FALSE),"") -> 0
C24: Cường | D24: F3-180 | E24: Tiệm ăn sáng NQ Phạm Đăng Giảng (Trạm Tân Phú) | F24: =_xlfn.IFNA(VLOOKUP($D24,Dulieutho,F$2,FALSE),"") -> 916 | G24: =_xlfn.IFNA(VLOOKUP($D24,Dulieutho,G$2,FALSE),"") -> 104 | H24: =_xlfn.IFNA(VLOOKUP($D24,Dulieutho,H$2,FALSE),"") -> 150 | I24: =_xlfn.IFNA(VLOOKUP($D24,Dulieutho,I$2,FALSE),"") -> 168 | J24: =_xlfn.IFNA(VLOOKUP($D24,Dulieutho,J$2,FALSE),"") -> 270 | K24: =_xlfn.IFNA(VLOOKUP($D24,Dulieutho,K$2,FALSE),"") -> 720 | L24: =_xlfn.IFNA(VLOOKUP($D24,Dulieutho,L$2,FALSE),"") -> 110 | M24: =_xlfn.IFNA(VLOOKUP($D24,Dulieutho,M$2,FALSE),"") -> 1 | ... AO24: =_xlfn.IFNA(VLOOKUP($D24,Dulieutho,AO$2,FALSE),"") -> 0
C25: Cường | D25: F1-176 | E25: Tiệm ăn sáng NQ Phạm Hữu Lầu (Trạm Chánh Hưng) | F25: =_xlfn.IFNA(VLOOKUP($D25,Dulieutho,F$2,FALSE),"") -> 460 | G25: =_xlfn.IFNA(VLOOKUP($D25,Dulieutho,G$2,FALSE),"") -> 48 | H25: =_xlfn.IFNA(VLOOKUP($D25,Dulieutho,H$2,FALSE),"") -> 60 | I25: =_xlfn.IFNA(VLOOKUP($D25,Dulieutho,I$2,FALSE),"") -> 24 | J25: =_xlfn.IFNA(VLOOKUP($D25,Dulieutho,J$2,FALSE),"") -> 90 | K25: =_xlfn.IFNA(VLOOKUP($D25,Dulieutho,K$2,FALSE),"") -> 660 | L25: =_xlfn.IFNA(VLOOKUP($D25,Dulieutho,L$2,FALSE),"") -> 120 | M25: =_xlfn.IFNA(VLOOKUP($D25,Dulieutho,M$2,FALSE),"") -> 1 | ... AO25: =_xlfn.IFNA(VLOOKUP($D25,Dulieutho,AO$2,FALSE),"") -> 0
C26: Cường | D26: F3-278 | E26: Tiệm ăn sáng NQ Phan Văn Trị ( Trạm Chánh Hưng) | F26: =_xlfn.IFNA(VLOOKUP($D26,Dulieutho,F$2,FALSE),"") -> 812 | G26: =_xlfn.IFNA(VLOOKUP($D26,Dulieutho,G$2,FALSE),"") -> 128 | H26: =_xlfn.IFNA(VLOOKUP($D26,Dulieutho,H$2,FALSE),"") -> 280 | I26: =_xlfn.IFNA(VLOOKUP($D26,Dulieutho,I$2,FALSE),"") -> 384 | J26: =_xlfn.IFNA(VLOOKUP($D26,Dulieutho,J$2,FALSE),"") -> 360 | K26: =_xlfn.IFNA(VLOOKUP($D26,Dulieutho,K$2,FALSE),"") -> 600 | L26: =_xlfn.IFNA(VLOOKUP($D26,Dulieutho,L$2,FALSE),"") -> 130 | M26: =_xlfn.IFNA(VLOOKUP($D26,Dulieutho,M$2,FALSE),"") -> 0 | ... AO26: =_xlfn.IFNA(VLOOKUP($D26,Dulieutho,AO$2,FALSE),"") -> 0
C27: Cường | D27: F5-131 | E27: Tiệm ăn sáng NQ Phú Xuân (Trạm CH) | F27: =_xlfn.IFNA(VLOOKUP($D27,Dulieutho,F$2,FALSE),"") -> 1620 | G27: =_xlfn.IFNA(VLOOKUP($D27,Dulieutho,G$2,FALSE),"") -> 192 | H27: =_xlfn.IFNA(VLOOKUP($D27,Dulieutho,H$2,FALSE),"") -> 130 | I27: =_xlfn.IFNA(VLOOKUP($D27,Dulieutho,I$2,FALSE),"") -> 216 | J27: =_xlfn.IFNA(VLOOKUP($D27,Dulieutho,J$2,FALSE),"") -> 630 | K27: =_xlfn.IFNA(VLOOKUP($D27,Dulieutho,K$2,FALSE),"") -> 720 | L27: =_xlfn.IFNA(VLOOKUP($D27,Dulieutho,L$2,FALSE),"") -> 140 | M27: =_xlfn.IFNA(VLOOKUP($D27,Dulieutho,M$2,FALSE),"") -> 3 | ... AO27: =_xlfn.IFNA(VLOOKUP($D27,Dulieutho,AO$2,FALSE),"") -> 0
C28: Cường | D28: F6-148 | E28: Tiệm ăn sáng NQ Sông Giồng (Trạm Thủ Đức) | F28: =_xlfn.IFNA(VLOOKUP($D28,Dulieutho,F$2,FALSE),"") -> 688 | G28: =_xlfn.IFNA(VLOOKUP($D28,Dulieutho,G$2,FALSE),"") -> 116 | H28: =_xlfn.IFNA(VLOOKUP($D28,Dulieutho,H$2,FALSE),"") -> 100 | I28: =_xlfn.IFNA(VLOOKUP($D28,Dulieutho,I$2,FALSE),"") -> 240 | J28: =_xlfn.IFNA(VLOOKUP($D28,Dulieutho,J$2,FALSE),"") -> 270 | K28: =_xlfn.IFNA(VLOOKUP($D28,Dulieutho,K$2,FALSE),"") -> 600 | L28: =_xlfn.IFNA(VLOOKUP($D28,Dulieutho,L$2,FALSE),"") -> 130 | M28: =_xlfn.IFNA(VLOOKUP($D28,Dulieutho,M$2,FALSE),"") -> 3 | ... AO28: =_xlfn.IFNA(VLOOKUP($D28,Dulieutho,AO$2,FALSE),"") -> 0
C29: Cường | D29: F1-209 | E29: Tiệm ăn sáng NQ Tôn Thất Thuyết (Trạm Chánh Hưng) | F29: =_xlfn.IFNA(VLOOKUP($D29,Dulieutho,F$2,FALSE),"") -> 728 | G29: =_xlfn.IFNA(VLOOKUP($D29,Dulieutho,G$2,FALSE),"") -> 100 | H29: =_xlfn.IFNA(VLOOKUP($D29,Dulieutho,H$2,FALSE),"") -> 210 | I29: =_xlfn.IFNA(VLOOKUP($D29,Dulieutho,I$2,FALSE),"") -> 288 | J29: =_xlfn.IFNA(VLOOKUP($D29,Dulieutho,J$2,FALSE),"") -> 1440 | K29: =_xlfn.IFNA(VLOOKUP($D29,Dulieutho,K$2,FALSE),"") -> 1740 | L29: =_xlfn.IFNA(VLOOKUP($D29,Dulieutho,L$2,FALSE),"") -> 400 | M29: =_xlfn.IFNA(VLOOKUP($D29,Dulieutho,M$2,FALSE),"") -> 1 | ... AO29: =_xlfn.IFNA(VLOOKUP($D29,Dulieutho,AO$2,FALSE),"") -> 0
C30: Cường | D30: F5-220 | E30: Tiệm ăn sáng NQ Trung Mỹ Tây (Trạm Tân Phú) | F30: =_xlfn.IFNA(VLOOKUP($D30,Dulieutho,F$2,FALSE),"") -> 644 | G30: =_xlfn.IFNA(VLOOKUP($D30,Dulieutho,G$2,FALSE),"") -> 96 | H30: =_xlfn.IFNA(VLOOKUP($D30,Dulieutho,H$2,FALSE),"") -> 80 | I30: =_xlfn.IFNA(VLOOKUP($D30,Dulieutho,I$2,FALSE),"") -> 24 | J30: =_xlfn.IFNA(VLOOKUP($D30,Dulieutho,J$2,FALSE),"") -> 270 | K30: =_xlfn.IFNA(VLOOKUP($D30,Dulieutho,K$2,FALSE),"") -> 420 | L30: =_xlfn.IFNA(VLOOKUP($D30,Dulieutho,L$2,FALSE),"") -> 100 | M30: =_xlfn.IFNA(VLOOKUP($D30,Dulieutho,M$2,FALSE),"") -> 0 | ... AO30: =_xlfn.IFNA(VLOOKUP($D30,Dulieutho,AO$2,FALSE),"") -> 100
C31: Cường | D31: F6-204 | E31: Tiệm ăn sáng NQ Trương Văn Bang (Trạm Thủ Đức) | F31: =_xlfn.IFNA(VLOOKUP($D31,Dulieutho,F$2,FALSE),"") -> 1248 | G31: =_xlfn.IFNA(VLOOKUP($D31,Dulieutho,G$2,FALSE),"") -> 116 | H31: =_xlfn.IFNA(VLOOKUP($D31,Dulieutho,H$2,FALSE),"") -> 180 | I31: =_xlfn.IFNA(VLOOKUP($D31,Dulieutho,I$2,FALSE),"") -> 264 | J31: =_xlfn.IFNA(VLOOKUP($D31,Dulieutho,J$2,FALSE),"") -> 180 | K31: =_xlfn.IFNA(VLOOKUP($D31,Dulieutho,K$2,FALSE),"") -> 720 | L31: =_xlfn.IFNA(VLOOKUP($D31,Dulieutho,L$2,FALSE),"") -> 130 | M31: =_xlfn.IFNA(VLOOKUP($D31,Dulieutho,M$2,FALSE),"") -> 0 | ... AO31: =_xlfn.IFNA(VLOOKUP($D31,Dulieutho,AO$2,FALSE),"") -> 0
C32: Cường | D32: F1-076 | E32: Tiệm ăn sáng NQ Vĩnh Khánh (Trạm CH) | F32: =_xlfn.IFNA(VLOOKUP($D32,Dulieutho,F$2,FALSE),"") -> 1288 | G32: =_xlfn.IFNA(VLOOKUP($D32,Dulieutho,G$2,FALSE),"") -> 244 | H32: =_xlfn.IFNA(VLOOKUP($D32,Dulieutho,H$2,FALSE),"") -> 290 | I32: =_xlfn.IFNA(VLOOKUP($D32,Dulieutho,I$2,FALSE),"") -> 48 | J32: =_xlfn.IFNA(VLOOKUP($D32,Dulieutho,J$2,FALSE),"") -> 180 | K32: =_xlfn.IFNA(VLOOKUP($D32,Dulieutho,K$2,FALSE),"") -> 1020 | L32: =_xlfn.IFNA(VLOOKUP($D32,Dulieutho,L$2,FALSE),"") -> 140 | M32: =_xlfn.IFNA(VLOOKUP($D32,Dulieutho,M$2,FALSE),"") -> 3 | ... AO32: =_xlfn.IFNA(VLOOKUP($D32,Dulieutho,AO$2,FALSE),"") -> 0
... C97: Thế | D97: F5-187 | E97: Tiệm ăn sáng NQ Lê Đại Hành (Trạm SVH) | F97: =_xlfn.IFNA(VLOOKUP($D97,Dulieutho,F$2,FALSE),"") -> 412 | G97: =_xlfn.IFNA(VLOOKUP($D97,Dulieutho,G$2,FALSE),"") -> 60 | H97: =_xlfn.IFNA(VLOOKUP($D97,Dulieutho,H$2,FALSE),"") -> 170 | I97: =_xlfn.IFNA(VLOOKUP($D97,Dulieutho,I$2,FALSE),"") -> 240 | J97: =_xlfn.IFNA(VLOOKUP($D97,Dulieutho,J$2,FALSE),"") -> 270 | K97: =_xlfn.IFNA(VLOOKUP($D97,Dulieutho,K$2,FALSE),"") -> 240 | L97: =_xlfn.IFNA(VLOOKUP($D97,Dulieutho,L$2,FALSE),"") -> 60 | M97: =_xlfn.IFNA(VLOOKUP($D97,Dulieutho,M$2,FALSE),"") -> 0 | ... AO97: =_xlfn.IFNA(VLOOKUP($D97,Dulieutho,AO$2,FALSE),"") -> 0

Sheet QuyDoi_DonVi
D1: Qui cách nhập dữ liệu | E1: Theo kg | F1: Theo kg | G1: Theo kg | H1: Theo kg | I1: Theo kg | J1: Theo kg | K1: Theo chai | L1: Theo kg | M1: Theo kg | N1: Theo lít | O1: Theo kg | P1: Theo kg | Q1: Theo thùng | R1: Theo cuộn | S1: Theo bao
D2: Cách thức qui đổi | E2: 0.5 kg / bịch * 1000g | F2: 1kg/bịch *1000g | G2: kg * 1000g -> số gam 250g/bịch -> số gam chia 250 ra số bịch 1 bich làm được 16 bánh | H2: Như thông số nhập | I2: Như thông số nhập | J2: Như thông số nhập | K2: 1 chai * 9 ly | L2: Như thông số nhập | M2: Như thông số nhập | N2: 1 lít * 1000g | O2: 1 kg * 1000g | P2: 1 kg * 1000g | Q2: Như thông số nhập | R2: Như thông số nhập | S2: 1 bao * 250 cây
D3: Công thức qui đổi | E3: =0.5*1000 -> 500 | F3: =1*1000 -> 1000 | G3: =1*1000/250*16 -> 64 | K3: =1*9 -> 9 | N3: =1*1000 -> 1000 | O3: =1*1000 -> 1000 | P3: =1*1000 -> 1000 | S3: =1*250 -> 250
A4: MÃ NQ | B4: Quản lý | C4: Mã NQ | D4: NHƯỢNG QUYỀN | E4: Pate gan (g) | F4: Chà bông xốp (g) | G4: Jam Bon (miếng) | H4: Sữa bột (kg) | I4: Trà Đen (kg) | J4: Bột Kem Sữa Cacao (kg) | K4: Nước Ngọt pesi (ly) | L4: Đường (12kg/bao) (kg) | M4: Bột chanh (1kg/túi) | N4: Tương cà lớn (2 lít/bình) (g) | O4: Tương Mayonaise (1kg/bịch) | P4: Tương mù tạc (0.5kg/bịch) | Q4: Ly giấy in hình logo 1p30s | R4: Màng ép | S4: Ống hút (250 cây/bao)
A5: F1-022 | B5: Cường | C5: F1-115 | D5: Tiệm ăn sáng NQ Phước Kiểng 1 (Trạm CH) | E5: =IFERROR(_xlfn.IFNA(VLOOKUP($C5,Dulieutho,ChiTiet!M$2,FALSE),0)*$E$3,0) -> 0 | F5: =IFERROR(_xlfn.IFNA(VLOOKUP($C5,Dulieutho,ChiTiet!N$2,FALSE),0)*$F$3,0) -> 1000 | G5: =IFERROR(_xlfn.IFNA(VLOOKUP($C5,Dulieutho,ChiTiet!O$2,FALSE),0)*$G$3,0) -> 64 | H5: =IFERROR(_xlfn.IFNA(VLOOKUP($C5,Dulieutho,ChiTiet!P$2,FALSE),0),0) -> 0 | I5: =IFERROR(_xlfn.IFNA(VLOOKUP($C5,Dulieutho,ChiTiet!Q$2,FALSE),0),0) -> 1 | J5: =IFERROR(_xlfn.IFNA(VLOOKUP($C5,Dulieutho,ChiTiet!R$2,FALSE),0),0) -> 4 | K5: =IFERROR(_xlfn.IFNA(VLOOKUP($C5,Dulieutho,ChiTiet!S$2,FALSE)*$K$3,0),0) -> 324 | L5: =IFERROR(_xlfn.IFNA(VLOOKUP($C5,Dulieutho,ChiTiet!U$2,FALSE),0),0) -> 0 | M5: =IFERROR(_xlfn.IFNA(VLOOKUP($C5,Dulieutho,ChiTiet!T$2,FALSE),0),0) -> 0 | N5: =IFERROR(_xlfn.IFNA(VLOOKUP($C5,Dulieutho,ChiTiet!V$2,FALSE)*1000,0),0) -> 2000 | O5: =IFERROR(_xlfn.IFNA(VLOOKUP($C5,Dulieutho,ChiTiet!W$2,FALSE)*$O$3,0),0) -> 2000 | P5: =IFERROR(_xlfn.IFNA(VLOOKUP($C5,Dulieutho,ChiTiet!X$2,FALSE)*$P$3,0),0) -> 0 | Q5: =IFERROR(_xlfn.IFNA(VLOOKUP($C5,Dulieutho,ChiTiet!AG$2,FALSE),0),0) -> 1000 | R5: =IFERROR(_xlfn.IFNA(VLOOKUP($C5,Dulieutho,ChiTiet!AH$2,FALSE),0),0) -> 0 | S5: =IFERROR(_xlfn.IFNA(VLOOKUP($C5,Dulieutho,ChiTiet!AI$2,FALSE)*$S$3,0),0) -> 1000
B6: Cường | C6: F5-149 | D6: Tiệm ăn sáng NQ Âu Dương Lân (Trạm Chánh Hưng) | E6: =IFERROR(_xlfn.IFNA(VLOOKUP($C6,Dulieutho,ChiTiet!M$2,FALSE),0)*$E$3,0) -> 0 | F6: =IFERROR(_xlfn.IFNA(VLOOKUP($C6,Dulieutho,ChiTiet!N$2,FALSE),0)*$F$3,0) -> 0 | G6: =IFERROR(_xlfn.IFNA(VLOOKUP($C6,Dulieutho,ChiTiet!O$2,FALSE),0)*$G$3,0) -> 0 | H6: =IFERROR(_xlfn.IFNA(VLOOKUP($C6,Dulieutho,ChiTiet!P$2,FALSE),0),0) -> 0 | I6: =IFERROR(_xlfn.IFNA(VLOOKUP($C6,Dulieutho,ChiTiet!Q$2,FALSE),0),0) -> 0 | J6: =IFERROR(_xlfn.IFNA(VLOOKUP($C6,Dulieutho,ChiTiet!R$2,FALSE),0),0) -> 0 | K6: =IFERROR(_xlfn.IFNA(VLOOKUP($C6,Dulieutho,ChiTiet!S$2,FALSE)*$K$3,0),0) -> 0 | L6: =IFERROR(_xlfn.IFNA(VLOOKUP($C6,Dulieutho,ChiTiet!U$2,FALSE),0),0) -> 0 | M6: =IFERROR(_xlfn.IFNA(VLOOKUP($C6,Dulieutho,ChiTiet!T$2,FALSE),0),0) -> 0 | N6: =IFERROR(_xlfn.IFNA(VLOOKUP($C6,Dulieutho,ChiTiet!V$2,FALSE)*1000,0),0) -> 0 | O6: =IFERROR(_xlfn.IFNA(VLOOKUP($C6,Dulieutho,ChiTiet!W$2,FALSE)*$O$3,0),0) -> 0 | P6: =IFERROR(_xlfn.IFNA(VLOOKUP($C6,Dulieutho,ChiTiet!X$2,FALSE)*$P$3,0),0) -> 0 | Q6: =IFERROR(_xlfn.IFNA(VLOOKUP($C6,Dulieutho,ChiTiet!AG$2,FALSE),0),0) -> 0 | R6: =IFERROR(_xlfn.IFNA(VLOOKUP($C6,Dulieutho,ChiTiet!AH$2,FALSE),0),0) -> 0 | S6: =IFERROR(_xlfn.IFNA(VLOOKUP($C6,Dulieutho,ChiTiet!AI$2,FALSE)*$S$3,0),0) -> 0
B7: Cường | C7: F6-260 | D7: Tiệm ăn sáng NQ Cô Giang 1 (Trạm SVH) | E7: =IFERROR(_xlfn.IFNA(VLOOKUP($C7,Dulieutho,ChiTiet!M$2,FALSE),0)*$E$3,0) -> 0 | F7: =IFERROR(_xlfn.IFNA(VLOOKUP($C7,Dulieutho,ChiTiet!N$2,FALSE),0)*$F$3,0) -> 2000 | G7: =IFERROR(_xlfn.IFNA(VLOOKUP($C7,Dulieutho,ChiTiet!O$2,FALSE),0)*$G$3,0) -> 0 | H7: =IFERROR(_xlfn.IFNA(VLOOKUP($C7,Dulieutho,ChiTiet!P$2,FALSE),0),0) -> 0 | I7: =IFERROR(_xlfn.IFNA(VLOOKUP($C7,Dulieutho,ChiTiet!Q$2,FALSE),0),0) -> 3 | J7: =IFERROR(_xlfn.IFNA(VLOOKUP($C7,Dulieutho,ChiTiet!R$2,FALSE),0),0) -> 21 | K7: =IFERROR(_xlfn.IFNA(VLOOKUP($C7,Dulieutho,ChiTiet!S$2,FALSE)*$K$3,0),0) -> 0 | L7: =IFERROR(_xlfn.IFNA(VLOOKUP($C7,Dulieutho,ChiTiet!U$2,FALSE),0),0) -> 0 | M7: =IFERROR(_xlfn.IFNA(VLOOKUP($C7,Dulieutho,ChiTiet!T$2,FALSE),0),0) -> 12 | N7: =IFERROR(_xlfn.IFNA(VLOOKUP($C7,Dulieutho,ChiTiet!V$2,FALSE)*1000,0),0) -> 4000 | O7: =IFERROR(_xlfn.IFNA(VLOOKUP($C7,Dulieutho,ChiTiet!W$2,FALSE)*$O$3,0),0) -> 12000 | P7: =IFERROR(_xlfn.IFNA(VLOOKUP($C7,Dulieutho,ChiTiet!X$2,FALSE)*$P$3,0),0) -> 500 | Q7: =IFERROR(_xlfn.IFNA(VLOOKUP($C7,Dulieutho,ChiTiet!AG$2,FALSE),0),0) -> 0 | R7: =IFERROR(_xlfn.IFNA(VLOOKUP($C7,Dulieutho,ChiTiet!AH$2,FALSE),0),0) -> 0 | S7: =IFERROR(_xlfn.IFNA(VLOOKUP($C7,Dulieutho,ChiTiet!AI$2,FALSE)*$S$3,0),0) -> 0
B8: Cường | C8: F3-041 | D8: Tiệm ăn sáng NQ Đinh Tiên Hoàng (Trạm SVH) | E8: =IFERROR(_xlfn.IFNA(VLOOKUP($C8,Dulieutho,ChiTiet!M$2,FALSE),0)*$E$3,0) -> 0 | F8: =IFERROR(_xlfn.IFNA(VLOOKUP($C8,Dulieutho,ChiTiet!N$2,FALSE),0)*$F$3,0) -> 0 | G8: =IFERROR(_xlfn.IFNA(VLOOKUP($C8,Dulieutho,ChiTiet!O$2,FALSE),0)*$G$3,0) -> 0 | H8: =IFERROR(_xlfn.IFNA(VLOOKUP($C8,Dulieutho,ChiTiet!P$2,FALSE),0),0) -> 0 | I8: =IFERROR(_xlfn.IFNA(VLOOKUP($C8,Dulieutho,ChiTiet!Q$2,FALSE),0),0) -> 0 | J8: =IFERROR(_xlfn.IFNA(VLOOKUP($C8,Dulieutho,ChiTiet!R$2,FALSE),0),0) -> 0 | K8: =IFERROR(_xlfn.IFNA(VLOOKUP($C8,Dulieutho,ChiTiet!S$2,FALSE)*$K$3,0),0) -> 0 | L8: =IFERROR(_xlfn.IFNA(VLOOKUP($C8,Dulieutho,ChiTiet!U$2,FALSE),0),0) -> 0 | M8: =IFERROR(_xlfn.IFNA(VLOOKUP($C8,Dulieutho,ChiTiet!T$2,FALSE),0),0) -> 0 | N8: =IFERROR(_xlfn.IFNA(VLOOKUP($C8,Dulieutho,ChiTiet!V$2,FALSE)*1000,0),0) -> 0 | O8: =IFERROR(_xlfn.IFNA(VLOOKUP($C8,Dulieutho,ChiTiet!W$2,FALSE)*$O$3,0),0) -> 0 | P8: =IFERROR(_xlfn.IFNA(VLOOKUP($C8,Dulieutho,ChiTiet!X$2,FALSE)*$P$3,0),0) -> 0 | Q8: =IFERROR(_xlfn.IFNA(VLOOKUP($C8,Dulieutho,ChiTiet!AG$2,FALSE),0),0) -> 0 | R8: =IFERROR(_xlfn.IFNA(VLOOKUP($C8,Dulieutho,ChiTiet!AH$2,FALSE),0),0) -> 0 | S8: =IFERROR(_xlfn.IFNA(VLOOKUP($C8,Dulieutho,ChiTiet!AI$2,FALSE)*$S$3,0),0) -> 0
B9: Cường | C9: F5-096 | D9: Tiệm ăn sáng NQ Đồng Nai (Trạm SVH) | E9: =IFERROR(_xlfn.IFNA(VLOOKUP($C9,Dulieutho,ChiTiet!M$2,FALSE),0)*$E$3,0) -> 1000 | F9: =IFERROR(_xlfn.IFNA(VLOOKUP($C9,Dulieutho,ChiTiet!N$2,FALSE),0)*$F$3,0) -> 1000 | G9: =IFERROR(_xlfn.IFNA(VLOOKUP($C9,Dulieutho,ChiTiet!O$2,FALSE),0)*$G$3,0) -> 128 | H9: =IFERROR(_xlfn.IFNA(VLOOKUP($C9,Dulieutho,ChiTiet!P$2,FALSE),0),0) -> 25 | I9: =IFERROR(_xlfn.IFNA(VLOOKUP($C9,Dulieutho,ChiTiet!Q$2,FALSE),0),0) -> 8 | J9: =IFERROR(_xlfn.IFNA(VLOOKUP($C9,Dulieutho,ChiTiet!R$2,FALSE),0),0) -> 39 | K9: =IFERROR(_xlfn.IFNA(VLOOKUP($C9,Dulieutho,ChiTiet!S$2,FALSE)*$K$3,0),0) -> 648 | L9: =IFERROR(_xlfn.IFNA(VLOOKUP($C9,Dulieutho,ChiTiet!U$2,FALSE),0),0) -> 36 | M9: =IFERROR(_xlfn.IFNA(VLOOKUP($C9,Dulieutho,ChiTiet!T$2,FALSE),0),0) -> 11 | N9: =IFERROR(_xlfn.IFNA(VLOOKUP($C9,Dulieutho,ChiTiet!V$2,FALSE)*1000,0),0) -> 20000 | O9: =IFERROR(_xlfn.IFNA(VLOOKUP($C9,Dulieutho,ChiTiet!W$2,FALSE)*$O$3,0),0) -> 10000 | P9: =IFERROR(_xlfn.IFNA(VLOOKUP($C9,Dulieutho,ChiTiet!X$2,FALSE)*$P$3,0),0) -> 500 | Q9: =IFERROR(_xlfn.IFNA(VLOOKUP($C9,Dulieutho,ChiTiet!AG$2,FALSE),0),0) -> 3000 | R9: =IFERROR(_xlfn.IFNA(VLOOKUP($C9,Dulieutho,ChiTiet!AH$2,FALSE),0),0) -> 1 | S9: =IFERROR(_xlfn.IFNA(VLOOKUP($C9,Dulieutho,ChiTiet!AI$2,FALSE)*$S$3,0),0) -> 3000
B10: Cường | C10: F7-235 | D10: Tiệm ăn sáng NQ Hóc Môn (Trạm Tân Phú) | E10: =IFERROR(_xlfn.IFNA(VLOOKUP($C10,Dulieutho,ChiTiet!M$2,FALSE),0)*$E$3,0) -> 500 | F10: =IFERROR(_xlfn.IFNA(VLOOKUP($C10,Dulieutho,ChiTiet!N$2,FALSE),0)*$F$3,0) -> 1000 | G10: =IFERROR(_xlfn.IFNA(VLOOKUP($C10,Dulieutho,ChiTiet!O$2,FALSE),0)*$G$3,0) -> 32 | H10: =IFERROR(_xlfn.IFNA(VLOOKUP($C10,Dulieutho,ChiTiet!P$2,FALSE),0),0) -> 0 | I10: =IFERROR(_xlfn.IFNA(VLOOKUP($C10,Dulieutho,ChiTiet!Q$2,FALSE),0),0) -> 1 | J10: =IFERROR(_xlfn.IFNA(VLOOKUP($C10,Dulieutho,ChiTiet!R$2,FALSE),0),0) -> 11 | K10: =IFERROR(_xlfn.IFNA(VLOOKUP($C10,Dulieutho,ChiTiet!S$2,FALSE)*$K$3,0),0) -> 1188 | L10: =IFERROR(_xlfn.IFNA(VLOOKUP($C10,Dulieutho,ChiTiet!U$2,FALSE),0),0) -> 24 | M10: =IFERROR(_xlfn.IFNA(VLOOKUP($C10,Dulieutho,ChiTiet!T$2,FALSE),0),0) -> 6 | N10: =IFERROR(_xlfn.IFNA(VLOOKUP($C10,Dulieutho,ChiTiet!V$2,FALSE)*1000,0),0) -> 14000 | O10: =IFERROR(_xlfn.IFNA(VLOOKUP($C10,Dulieutho,ChiTiet!W$2,FALSE)*$O$3,0),0) -> 10000 | P10: =IFERROR(_xlfn.IFNA(VLOOKUP($C10,Dulieutho,ChiTiet!X$2,FALSE)*$P$3,0),0) -> 1000 | Q10: =IFERROR(_xlfn.IFNA(VLOOKUP($C10,Dulieutho,ChiTiet!AG$2,FALSE),0),0) -> 2000 | R10: =IFERROR(_xlfn.IFNA(VLOOKUP($C10,Dulieutho,ChiTiet!AH$2,FALSE),0),0) -> 1 | S10: =IFERROR(_xlfn.IFNA(VLOOKUP($C10,Dulieutho,ChiTiet!AI$2,FALSE)*$S$3,0),0) -> 2000
B11: Cường | C11: F1-184 | D11: Tiệm ăn sáng NQ Huỳnh Tấn Phát (Trạm Chánh Hưng) | E11: =IFERROR(_xlfn.IFNA(VLOOKUP($C11,Dulieutho,ChiTiet!M$2,FALSE),0)*$E$3,0) -> 500 | F11: =IFERROR(_xlfn.IFNA(VLOOKUP($C11,Dulieutho,ChiTiet!N$2,FALSE),0)*$F$3,0) -> 1000 | G11: =IFERROR(_xlfn.IFNA(VLOOKUP($C11,Dulieutho,ChiTiet!O$2,FALSE),0)*$G$3,0) -> 256 | H11: =IFERROR(_xlfn.IFNA(VLOOKUP($C11,Dulieutho,ChiTiet!P$2,FALSE),0),0) -> 25 | I11: =IFERROR(_xlfn.IFNA(VLOOKUP($C11,Dulieutho,ChiTiet!Q$2,FALSE),0),0) -> 3 | J11: =IFERROR(_xlfn.IFNA(VLOOKUP($C11,Dulieutho,ChiTiet!R$2,FALSE),0),0) -> 32 | K11: =IFERROR(_xlfn.IFNA(VLOOKUP($C11,Dulieutho,ChiTiet!S$2,FALSE)*$K$3,0),0) -> 1404 | L11: =IFERROR(_xlfn.IFNA(VLOOKUP($C11,Dulieutho,ChiTiet!U$2,FALSE),0),0) -> 12 | M11: =IFERROR(_xlfn.IFNA(VLOOKUP($C11,Dulieutho,ChiTiet!T$2,FALSE),0),0) -> 10 | N11: =IFERROR(_xlfn.IFNA(VLOOKUP($C11,Dulieutho,ChiTiet!V$2,FALSE)*1000,0),0) -> 18000 | O11: =IFERROR(_xlfn.IFNA(VLOOKUP($C11,Dulieutho,ChiTiet!W$2,FALSE)*$O$3,0),0) -> 18000 | P11: =IFERROR(_xlfn.IFNA(VLOOKUP($C11,Dulieutho,ChiTiet!X$2,FALSE)*$P$3,0),0) -> 1500 | Q11: =IFERROR(_xlfn.IFNA(VLOOKUP($C11,Dulieutho,ChiTiet!AG$2,FALSE),0),0) -> 5000 | R11: =IFERROR(_xlfn.IFNA(VLOOKUP($C11,Dulieutho,ChiTiet!AH$2,FALSE),0),0) -> 1 | S11: =IFERROR(_xlfn.IFNA(VLOOKUP($C11,Dulieutho,ChiTiet!AI$2,FALSE)*$S$3,0),0) -> 5000
B12: Cường | C12: F2-036 | D12: Tiệm ăn sáng NQ Huỳnh Tịnh Của (Trạm SVH) | E12: =IFERROR(_xlfn.IFNA(VLOOKUP($C12,Dulieutho,ChiTiet!M$2,FALSE),0)*$E$3,0) -> 0 | F12: =IFERROR(_xlfn.IFNA(VLOOKUP($C12,Dulieutho,ChiTiet!N$2,FALSE),0)*$F$3,0) -> 0 | G12: =IFERROR(_xlfn.IFNA(VLOOKUP($C12,Dulieutho,ChiTiet!O$2,FALSE),0)*$G$3,0) -> 128 | H12: =IFERROR(_xlfn.IFNA(VLOOKUP($C12,Dulieutho,ChiTiet!P$2,FALSE),0),0) -> 50 | I12: =IFERROR(_xlfn.IFNA(VLOOKUP($C12,Dulieutho,ChiTiet!Q$2,FALSE),0),0) -> 6 | J12: =IFERROR(_xlfn.IFNA(VLOOKUP($C12,Dulieutho,ChiTiet!R$2,FALSE),0),0) -> 21.5 | K12: =IFERROR(_xlfn.IFNA(VLOOKUP($C12,Dulieutho,ChiTiet!S$2,FALSE)*$K$3,0),0) -> 540 | L12: =IFERROR(_xlfn.IFNA(VLOOKUP($C12,Dulieutho,ChiTiet!U$2,FALSE),0),0) -> 36 | M12: =IFERROR(_xlfn.IFNA(VLOOKUP($C12,Dulieutho,ChiTiet!T$2,FALSE),0),0) -> 0 | N12: =IFERROR(_xlfn.IFNA(VLOOKUP($C12,Dulieutho,ChiTiet!V$2,FALSE)*1000,0),0) -> 28000 | O12: =IFERROR(_xlfn.IFNA(VLOOKUP($C12,Dulieutho,ChiTiet!W$2,FALSE)*$O$3,0),0) -> 19000 | P12: =IFERROR(_xlfn.IFNA(VLOOKUP($C12,Dulieutho,ChiTiet!X$2,FALSE)*$P$3,0),0) -> 0 | Q12: =IFERROR(_xlfn.IFNA(VLOOKUP($C12,Dulieutho,ChiTiet!AG$2,FALSE),0),0) -> 3000 | R12: =IFERROR(_xlfn.IFNA(VLOOKUP($C12,Dulieutho,ChiTiet!AH$2,FALSE),0),0) -> 1 | S12: =IFERROR(_xlfn.IFNA(VLOOKUP($C12,Dulieutho,ChiTiet!AI$2,FALSE)*$S$3,0),0) -> 3000
B13: Cường | C13: F6-071 | D13: Tiệm ăn sáng NQ Kỳ Đồng (Trạm SVH) | E13: =IFERROR(_xlfn.IFNA(VLOOKUP($C13,Dulieutho,ChiTiet!M$2,FALSE),0)*$E$3,0) -> 500 | F13: =IFERROR(_xlfn.IFNA(VLOOKUP($C13,Dulieutho,ChiTiet!N$2,FALSE),0)*$F$3,0) -> 2000 | G13: =IFERROR(_xlfn.IFNA(VLOOKUP($C13,Dulieutho,ChiTiet!O$2,FALSE),0)*$G$3,0) -> 64 | H13: =IFERROR(_xlfn.IFNA(VLOOKUP($C13,Dulieutho,ChiTiet!P$2,FALSE),0),0) -> 0 | I13: =IFERROR(_xlfn.IFNA(VLOOKUP($C13,Dulieutho,ChiTiet!Q$2,FALSE),0),0) -> 1 | J13: =IFERROR(_xlfn.IFNA(VLOOKUP($C13,Dulieutho,ChiTiet!R$2,FALSE),0),0) -> 8.5 | K13: =IFERROR(_xlfn.IFNA(VLOOKUP($C13,Dulieutho,ChiTiet!S$2,FALSE)*$K$3,0),0) -> 216 | L13: =IFERROR(_xlfn.IFNA(VLOOKUP($C13,Dulieutho,ChiTiet!U$2,FALSE),0),0) -> 0 | M13: =IFERROR(_xlfn.IFNA(VLOOKUP($C13,Dulieutho,ChiTiet!T$2,FALSE),0),0) -> 4 | N13: =IFERROR(_xlfn.IFNA(VLOOKUP($C13,Dulieutho,ChiTiet!V$2,FALSE)*1000,0),0) -> 10000 | O13: =IFERROR(_xlfn.IFNA(VLOOKUP($C13,Dulieutho,ChiTiet!W$2,FALSE)*$O$3,0),0) -> 9000 | P13: =IFERROR(_xlfn.IFNA(VLOOKUP($C13,Dulieutho,ChiTiet!X$2,FALSE)*$P$3,0),0) -> 0 | Q13: =IFERROR(_xlfn.IFNA(VLOOKUP($C13,Dulieutho,ChiTiet!AG$2,FALSE),0),0) -> 1000 | R13: =IFERROR(_xlfn.IFNA(VLOOKUP($C13,Dulieutho,ChiTiet!AH$2,FALSE),0),0) -> 1 | S13: =IFERROR(_xlfn.IFNA(VLOOKUP($C13,Dulieutho,ChiTiet!AI$2,FALSE)*$S$3,0),0) -> 1000
B14: Cường | C14: F1-215 | D14: Tiệm ăn sáng NQ Lâm Văn Bền (Trạm Chánh Hưng) | E14: =IFERROR(_xlfn.IFNA(VLOOKUP($C14,Dulieutho,ChiTiet!M$2,FALSE),0)*$E$3,0) -> 1500 | F14: =IFERROR(_xlfn.IFNA(VLOOKUP($C14,Dulieutho,ChiTiet!N$2,FALSE),0)*$F$3,0) -> 1000 | G14: =IFERROR(_xlfn.IFNA(VLOOKUP($C14,Dulieutho,ChiTiet!O$2,FALSE),0)*$G$3,0) -> 64 | H14: =IFERROR(_xlfn.IFNA(VLOOKUP($C14,Dulieutho,ChiTiet!P$2,FALSE),0),0) -> 0 | I14: =IFERROR(_xlfn.IFNA(VLOOKUP($C14,Dulieutho,ChiTiet!Q$2,FALSE),0),0) -> 3 | J14: =IFERROR(_xlfn.IFNA(VLOOKUP($C14,Dulieutho,ChiTiet!R$2,FALSE),0),0) -> 8 | K14: =IFERROR(_xlfn.IFNA(VLOOKUP($C14,Dulieutho,ChiTiet!S$2,FALSE)*$K$3,0),0) -> 432 | L14: =IFERROR(_xlfn.IFNA(VLOOKUP($C14,Dulieutho,ChiTiet!U$2,FALSE),0),0) -> 24 | M14: =IFERROR(_xlfn.IFNA(VLOOKUP($C14,Dulieutho,ChiTiet!T$2,FALSE),0),0) -> 6 | N14: =IFERROR(_xlfn.IFNA(VLOOKUP($C14,Dulieutho,ChiTiet!V$2,FALSE)*1000,0),0) -> 18000 | O14: =IFERROR(_xlfn.IFNA(VLOOKUP($C14,Dulieutho,ChiTiet!W$2,FALSE)*$O$3,0),0) -> 13000 | P14: =IFERROR(_xlfn.IFNA(VLOOKUP($C14,Dulieutho,ChiTiet!X$2,FALSE)*$P$3,0),0) -> 1000 | Q14: =IFERROR(_xlfn.IFNA(VLOOKUP($C14,Dulieutho,ChiTiet!AG$2,FALSE),0),0) -> 2000 | R14: =IFERROR(_xlfn.IFNA(VLOOKUP($C14,Dulieutho,ChiTiet!AH$2,FALSE),0),0) -> 1 | S14: =IFERROR(_xlfn.IFNA(VLOOKUP($C14,Dulieutho,ChiTiet!AI$2,FALSE)*$S$3,0),0) -> 2000
B15: Cường | C15: F1-191 | D15: Tiệm ăn sáng NQ Lê Thánh Tôn (Trạm Chánh Hưng) | E15: =IFERROR(_xlfn.IFNA(VLOOKUP($C15,Dulieutho,ChiTiet!M$2,FALSE),0)*$E$3,0) -> 1500 | F15: =IFERROR(_xlfn.IFNA(VLOOKUP($C15,Dulieutho,ChiTiet!N$2,FALSE),0)*$F$3,0) -> 1000 | G15: =IFERROR(_xlfn.IFNA(VLOOKUP($C15,Dulieutho,ChiTiet!O$2,FALSE),0)*$G$3,0) -> 96 | H15: =IFERROR(_xlfn.IFNA(VLOOKUP($C15,Dulieutho,ChiTiet!P$2,FALSE),0),0) -> 25 | I15: =IFERROR(_xlfn.IFNA(VLOOKUP($C15,Dulieutho,ChiTiet!Q$2,FALSE),0),0) -> 2 | J15: =IFERROR(_xlfn.IFNA(VLOOKUP($C15,Dulieutho,ChiTiet!R$2,FALSE),0),0) -> 3 | K15: =IFERROR(_xlfn.IFNA(VLOOKUP($C15,Dulieutho,ChiTiet!S$2,FALSE)*$K$3,0),0) -> 432 | L15: =IFERROR(_xlfn.IFNA(VLOOKUP($C15,Dulieutho,ChiTiet!U$2,FALSE),0),0) -> 24 | M15: =IFERROR(_xlfn.IFNA(VLOOKUP($C15,Dulieutho,ChiTiet!T$2,FALSE),0),0) -> 5 | N15: =IFERROR(_xlfn.IFNA(VLOOKUP($C15,Dulieutho,ChiTiet!V$2,FALSE)*1000,0),0) -> 14000 | O15: =IFERROR(_xlfn.IFNA(VLOOKUP($C15,Dulieutho,ChiTiet!W$2,FALSE)*$O$3,0),0) -> 12000 | P15: =IFERROR(_xlfn.IFNA(VLOOKUP($C15,Dulieutho,ChiTiet!X$2,FALSE)*$P$3,0),0) -> 1500 | Q15: =IFERROR(_xlfn.IFNA(VLOOKUP($C15,Dulieutho,ChiTiet!AG$2,FALSE),0),0) -> 2000 | R15: =IFERROR(_xlfn.IFNA(VLOOKUP($C15,Dulieutho,ChiTiet!AH$2,FALSE),0),0) -> 1 | S15: =IFERROR(_xlfn.IFNA(VLOOKUP($C15,Dulieutho,ChiTiet!AI$2,FALSE)*$S$3,0),0) -> 2250
B16: Cường | C16: F6-145 | D16: Tiệm ăn sáng NQ Lương Đình Của (Trạm Thủ Đức) | E16: =IFERROR(_xlfn.IFNA(VLOOKUP($C16,Dulieutho,ChiTiet!M$2,FALSE),0)*$E$3,0) -> 500 | F16: =IFERROR(_xlfn.IFNA(VLOOKUP($C16,Dulieutho,ChiTiet!N$2,FALSE),0)*$F$3,0) -> 1000 | G16: =IFERROR(_xlfn.IFNA(VLOOKUP($C16,Dulieutho,ChiTiet!O$2,FALSE),0)*$G$3,0) -> 32 | H16: =IFERROR(_xlfn.IFNA(VLOOKUP($C16,Dulieutho,ChiTiet!P$2,FALSE),0),0) -> 0 | I16: =IFERROR(_xlfn.IFNA(VLOOKUP($C16,Dulieutho,ChiTiet!Q$2,FALSE),0),0) -> 2 | J16: =IFERROR(_xlfn.IFNA(VLOOKUP($C16,Dulieutho,ChiTiet!R$2,FALSE),0),0) -> 4 | K16: =IFERROR(_xlfn.IFNA(VLOOKUP($C16,Dulieutho,ChiTiet!S$2,FALSE)*$K$3,0),0) -> 432 | L16: =IFERROR(_xlfn.IFNA(VLOOKUP($C16,Dulieutho,ChiTiet!U$2,FALSE),0),0) -> 12 | M16: =IFERROR(_xlfn.IFNA(VLOOKUP($C16,Dulieutho,ChiTiet!T$2,FALSE),0),0) -> 2 | N16: =IFERROR(_xlfn.IFNA(VLOOKUP($C16,Dulieutho,ChiTiet!V$2,FALSE)*1000,0),0) -> 8000 | O16: =IFERROR(_xlfn.IFNA(VLOOKUP($C16,Dulieutho,ChiTiet!W$2,FALSE)*$O$3,0),0) -> 13000 | P16: =IFERROR(_xlfn.IFNA(VLOOKUP($C16,Dulieutho,ChiTiet!X$2,FALSE)*$P$3,0),0) -> 500 | Q16: =IFERROR(_xlfn.IFNA(VLOOKUP($C16,Dulieutho,ChiTiet!AG$2,FALSE),0),0) -> 1000 | R16: =IFERROR(_xlfn.IFNA(VLOOKUP($C16,Dulieutho,ChiTiet!AH$2,FALSE),0),0) -> 1 | S16: =IFERROR(_xlfn.IFNA(VLOOKUP($C16,Dulieutho,ChiTiet!AI$2,FALSE)*$S$3,0),0) -> 1000
B17: Cường | C17: F5-092 | D17: Tiệm ăn sáng NQ Nguyễn ảnh Thủ (Trạm GV) | E17: =IFERROR(_xlfn.IFNA(VLOOKUP($C17,Dulieutho,ChiTiet!M$2,FALSE),0)*$E$3,0) -> 2000 | F17: =IFERROR(_xlfn.IFNA(VLOOKUP($C17,Dulieutho,ChiTiet!N$2,FALSE),0)*$F$3,0) -> 1000 | G17: =IFERROR(_xlfn.IFNA(VLOOKUP($C17,Dulieutho,ChiTiet!O$2,FALSE),0)*$G$3,0) -> 256 | H17: =IFERROR(_xlfn.IFNA(VLOOKUP($C17,Dulieutho,ChiTiet!P$2,FALSE),0),0) -> 0 | I17: =IFERROR(_xlfn.IFNA(VLOOKUP($C17,Dulieutho,ChiTiet!Q$2,FALSE),0),0) -> 1 | J17: =IFERROR(_xlfn.IFNA(VLOOKUP($C17,Dulieutho,ChiTiet!R$2,FALSE),0),0) -> 9 | K17: =IFERROR(_xlfn.IFNA(VLOOKUP($C17,Dulieutho,ChiTiet!S$2,FALSE)*$K$3,0),0) -> 540 | L17: =IFERROR(_xlfn.IFNA(VLOOKUP($C17,Dulieutho,ChiTiet!U$2,FALSE),0),0) -> 24 | M17: =IFERROR(_xlfn.IFNA(VLOOKUP($C17,Dulieutho,ChiTiet!T$2,FALSE),0),0) -> 0 | N17: =IFERROR(_xlfn.IFNA(VLOOKUP($C17,Dulieutho,ChiTiet!V$2,FALSE)*1000,0),0) -> 12000 | O17: =IFERROR(_xlfn.IFNA(VLOOKUP($C17,Dulieutho,ChiTiet!W$2,FALSE)*$O$3,0),0) -> 10000 | P17: =IFERROR(_xlfn.IFNA(VLOOKUP($C17,Dulieutho,ChiTiet!X$2,FALSE)*$P$3,0),0) -> 1000 | Q17: =IFERROR(_xlfn.IFNA(VLOOKUP($C17,Dulieutho,ChiTiet!AG$2,FALSE),0),0) -> 1000 | R17: =IFERROR(_xlfn.IFNA(VLOOKUP($C17,Dulieutho,ChiTiet!AH$2,FALSE),0),0) -> 0 | S17: =IFERROR(_xlfn.IFNA(VLOOKUP($C17,Dulieutho,ChiTiet!AI$2,FALSE)*$S$3,0),0) -> 1000
... B98: Thế | C98: F5-187 | D98: Tiệm ăn sáng NQ Lê Đại Hành (Trạm SVH) | E98: =IFERROR(_xlfn.IFNA(VLOOKUP($C98,Dulieutho,ChiTiet!M$2,FALSE),0)*$E$3,0) -> 0 | F98: =IFERROR(_xlfn.IFNA(VLOOKUP($C98,Dulieutho,ChiTiet!N$2,FALSE),0)*$F$3,0) -> 0 | G98: =IFERROR(_xlfn.IFNA(VLOOKUP($C98,Dulieutho,ChiTiet!O$2,FALSE),0)*$G$3,0) -> 96 | H98: =IFERROR(_xlfn.IFNA(VLOOKUP($C98,Dulieutho,ChiTiet!P$2,FALSE),0),0) -> 0 | I98: =IFERROR(_xlfn.IFNA(VLOOKUP($C98,Dulieutho,ChiTiet!Q$2,FALSE),0),0) -> 2 | J98: =IFERROR(_xlfn.IFNA(VLOOKUP($C98,Dulieutho,ChiTiet!R$2,FALSE),0),0) -> 6.5 | K98: =IFERROR(_xlfn.IFNA(VLOOKUP($C98,Dulieutho,ChiTiet!S$2,FALSE)*$K$3,0),0) -> 216 | L98: =IFERROR(_xlfn.IFNA(VLOOKUP($C98,Dulieutho,ChiTiet!U$2,FALSE),0),0) -> 0 | M98: =IFERROR(_xlfn.IFNA(VLOOKUP($C98,Dulieutho,ChiTiet!T$2,FALSE),0),0) -> 2 | N98: =IFERROR(_xlfn.IFNA(VLOOKUP($C98,Dulieutho,ChiTiet!V$2,FALSE)*1000,0),0) -> 2000 | O98: =IFERROR(_xlfn.IFNA(VLOOKUP($C98,Dulieutho,ChiTiet!W$2,FALSE)*$O$3,0),0) -> 4000 | P98: =IFERROR(_xlfn.IFNA(VLOOKUP($C98,Dulieutho,ChiTiet!X$2,FALSE)*$P$3,0),0) -> 0 | Q98: =IFERROR(_xlfn.IFNA(VLOOKUP($C98,Dulieutho,ChiTiet!AG$2,FALSE),0),0) -> 0 | R98: =IFERROR(_xlfn.IFNA(VLOOKUP($C98,Dulieutho,ChiTiet!AH$2,FALSE),0),0) -> 0 | S98: =IFERROR(_xlfn.IFNA(VLOOKUP($C98,Dulieutho,ChiTiet!AI$2,FALSE)*$S$3,0),0) -> 0

Sheet SOP_Banh
A1: MÃ NQ | B1: Quản lý | C1: Mã NQ | D1: NHƯỢNG QUYỀN | E1: Bánh mì hamburger | F1: Bánh Mì Hotdog | G1: Bánh mì pita | H1: Bánh mì sandwich | I1: Thịt / Gà / Tôm/BTH (miếng) | J1: Tương Cà (g) | K1: Mayonaise (g) | L1: Dầu ăn (lít) | M1: Hộp / Túi / Giấy | N1: Pate (g) | O1: Jambong (bịch) | P1: Chà bông (g) | Q1: Xúc xích (cây) | R1: Túi đựng ly | S1: Ly | T1: Màng ép | U1: Ống Hút | V1: Hộp / Giấy Pita - Hamburger | W1: Túi Giấy Hotdog | X1: Hộp Giấy Sanwich
B2: Cường | C2: F1-115 | D2: Tiệm ăn sáng NQ Phước Kiểng 1 (Trạm CH) | E2: =_xlfn.IFNA(VLOOKUP($C2,Dulieutho,ChiTiet!F$2,FALSE),"") -> 492 | F2: =_xlfn.IFNA(VLOOKUP($C2,Dulieutho,ChiTiet!G$2,FALSE),"") -> 92 | G2: =_xlfn.IFNA(VLOOKUP($C2,Dulieutho,ChiTiet!H$2,FALSE),"") -> 70 | H2: =_xlfn.IFNA(VLOOKUP($C2,Dulieutho,ChiTiet!I$2,FALSE),"") -> 144 | I2: =IFERROR((E2+G2)*1,0) -> 562 | J2: =SUM(E2:G2)*5 -> 3270 | K2: =IFERROR(((E2+G2)*5)+(H2/2*5),0) -> 3170 | L2: =IFERROR((_xlfn.IFNA(VLOOKUP($C2,Dulieutho,ChiTiet!K$2,FALSE),"")+_xlfn.IFNA(VLOOKUP($C2,Dulieutho,ChiTiet!AK$2,FALSE),""))/80,0) -> 3.75 | M2: =IFERROR((E2+G2+F2+(H2/2))*1,0) -> 726 | N2: =IFERROR(H2/2*5,0) -> 360 | O2: =IFERROR(H2/2/16,0) -> 4.5 | P2: =IFERROR(H2/2*5,0) -> 360 | Q2: =IFERROR(F2*1,0) -> 92 | R2: =IFERROR((E2+G2+F2+(H2/2)*1),0) -> 726 | S2: =IFERROR((E2+G2+F2+(H2/2)*1),0) -> 726 | T2: =S2 -> 726 | U2: =S2 -> 726 | V2: =I2 -> 562 | W2: =F2 -> 92 | X2: =IFERROR(H2/2,0) -> 72
B3: Cường | C3: F5-149 | D3: Tiệm ăn sáng NQ Âu Dương Lân (Trạm Chánh Hưng) | E3: =_xlfn.IFNA(VLOOKUP($C3,Dulieutho,ChiTiet!F$2,FALSE),"") | F3: =_xlfn.IFNA(VLOOKUP($C3,Dulieutho,ChiTiet!G$2,FALSE),"") | G3: =_xlfn.IFNA(VLOOKUP($C3,Dulieutho,ChiTiet!H$2,FALSE),"") | H3: =_xlfn.IFNA(VLOOKUP($C3,Dulieutho,ChiTiet!I$2,FALSE),"") | I3: =IFERROR((E3+G3)*1,0) -> 0 | J3: =SUM(E3:G3)*5 -> 0 | K3: =IFERROR(((E3+G3)*5)+(H3/2*5),0) -> 0 | L3: =IFERROR((_xlfn.IFNA(VLOOKUP($C3,Dulieutho,ChiTiet!K$2,FALSE),"")+_xlfn.IFNA(VLOOKUP($C3,Dulieutho,ChiTiet!AK$2,FALSE),""))/80,0) -> 0 | M3: =IFERROR((E3+G3+F3+(H3/2))*1,0) -> 0 | N3: =IFERROR(H3/2*5,0) -> 0 | O3: =IFERROR(H3/2/16,0) -> 0 | P3: =IFERROR(H3/2*5,0) -> 0 | Q3: =IFERROR(F3*1,0) -> 0 | R3: =IFERROR((E3+G3+F3+(H3/2)*1),0) -> 0 | S3: =IFERROR((E3+G3+F3+(H3/2)*1),0) -> 0 | T3: =S3 -> 0 | U3: =S3 -> 0 | V3: =I3 -> 0 | W3: =F3 | X3: =IFERROR(H3/2,0) -> 0
B4: Cường | C4: F6-260 | D4: Tiệm ăn sáng NQ Cô Giang 1 (Trạm SVH) | E4: =_xlfn.IFNA(VLOOKUP($C4,Dulieutho,ChiTiet!F$2,FALSE),"") -> 360 | F4: =_xlfn.IFNA(VLOOKUP($C4,Dulieutho,ChiTiet!G$2,FALSE),"") -> 56 | G4: =_xlfn.IFNA(VLOOKUP($C4,Dulieutho,ChiTiet!H$2,FALSE),"") -> 150 | H4: =_xlfn.IFNA(VLOOKUP($C4,Dulieutho,ChiTiet!I$2,FALSE),"") -> 0 | I4: =IFERROR((E4+G4)*1,0) -> 510 | J4: =SUM(E4:G4)*5 -> 2830 | K4: =IFERROR(((E4+G4)*5)+(H4/2*5),0) -> 2550 | L4: =IFERROR((_xlfn.IFNA(VLOOKUP($C4,Dulieutho,ChiTiet!K$2,FALSE),"")+_xlfn.IFNA(VLOOKUP($C4,Dulieutho,ChiTiet!AK$2,FALSE),""))/80,0) -> 0 | M4: =IFERROR((E4+G4+F4+(H4/2))*1,0) -> 566 | N4: =IFERROR(H4/2*5,0) -> 0 | O4: =IFERROR(H4/2/16,0) -> 0 | P4: =IFERROR(H4/2*5,0) -> 0 | Q4: =IFERROR(F4*1,0) -> 56 | R4: =IFERROR((E4+G4+F4+(H4/2)*1),0) -> 566 | S4: =IFERROR((E4+G4+F4+(H4/2)*1),0) -> 566 | T4: =S4 -> 566 | U4: =S4 -> 566 | V4: =I4 -> 510 | W4: =F4 -> 56 | X4: =IFERROR(H4/2,0) -> 0
B5: Cường | C5: F3-041 | D5: Tiệm ăn sáng NQ Đinh Tiên Hoàng (Trạm SVH) | E5: =_xlfn.IFNA(VLOOKUP($C5,Dulieutho,ChiTiet!F$2,FALSE),"") | F5: =_xlfn.IFNA(VLOOKUP($C5,Dulieutho,ChiTiet!G$2,FALSE),"") | G5: =_xlfn.IFNA(VLOOKUP($C5,Dulieutho,ChiTiet!H$2,FALSE),"") | H5: =_xlfn.IFNA(VLOOKUP($C5,Dulieutho,ChiTiet!I$2,FALSE),"") | I5: =IFERROR((E5+G5)*1,0) -> 0 | J5: =SUM(E5:G5)*5 -> 0 | K5: =IFERROR(((E5+G5)*5)+(H5/2*5),0) -> 0 | L5: =IFERROR((_xlfn.IFNA(VLOOKUP($C5,Dulieutho,ChiTiet!K$2,FALSE),"")+_xlfn.IFNA(VLOOKUP($C5,Dulieutho,ChiTiet!AK$2,FALSE),""))/80,0) -> 0 | M5: =IFERROR((E5+G5+F5+(H5/2))*1,0) -> 0 | N5: =IFERROR(H5/2*5,0) -> 0 | O5: =IFERROR(H5/2/16,0) -> 0 | P5: =IFERROR(H5/2*5,0) -> 0 | Q5: =IFERROR(F5*1,0) -> 0 | R5: =IFERROR((E5+G5+F5+(H5/2)*1),0) -> 0 | S5: =IFERROR((E5+G5+F5+(H5/2)*1),0) -> 0 | T5: =S5 -> 0 | U5: =S5 -> 0 | V5: =I5 -> 0 | W5: =F5 | X5: =IFERROR(H5/2,0) -> 0
